Workbook

Sheet Gasoline and electric vehicles
A1: kg/t conversion factor | B1: 1000
A2: g/kg | B2: 1000 | AD2: Gas Vehicle spreadsheet calculations | AE2: Gas Vehicle Open LCA | AF2: Electric Vehicle spreadsheet calculations | AG2: Electric Vehicle Open LCA | AH2: Electric Vehicle - Wind spreadsheet calculations | AI2: Electric Vehicle-Wind Open LCA | AJ2: Electric Vehicle - Photovoltaic spreadsheet calculations | AK2: Electric Vehicle - Photovoltaic Open LCA | AL2: Electric Vehicle - Hard coal spreadsheet calculations | AO2: GHG CO2equ. kgCO2equ over lifetime | AP2: Cumulative graph | AV2: GHG CO2equ. kgCO2equ/FU | AW2: Graph per FU
AC3: Lifetime distance km | AD3: 150000 | AF3: =1.5*$AD3 -> 225000 | AH3: =1.5*$AD3 -> 225000 | AJ3: =1.5*$AD3 -> 225000 | AL3: =1.5*$AD3 -> 225000
A4: Transportation by Gas Vehicle FU= 1 vehicle km Life Cycle stage (150,000 km lifespan) | B4: Quantity per FU | C4: Unit | D4: Energy/Unit [MJ/Unit] | E4: Energy per FU [MJ/FU] | F4: fraction | G4: CO2/Unit [kg/unit] | H4: CO2 fossil/FU | I4: fraction2 | J4: Check g CO2/MJ | K4: CO2equ/Unit [kg/unit]2 | L4: CO2equ./FU | M4: fraction3 | O4: Energy MJ/FU | P4: Gas Vehicle | Q4: Electric Vehicle | R4: Electric Vehicle - Wind | S4: Electric Vehicle - Photovoltaic | T4: Electric Vehicle - hard coal | V4: Fossil CO2 kgCO2/FU | W4: Gas Vehicle | X4: Electric Vehicle | Y4: Electric Vehicle - Wind | Z4: Electric Vehicle - Photovoltaic | AA4: Electric Vehicle - hard coal | AC4: GHG CO2equ. kgCO2equ/FU | AD4: Gas Vehicle | AF4: Electric Vehicle - EU mix | AH4: Electric Vehicle - Wind | AJ4: Electric Vehicle - Photovoltaic | AL4: Electric Vehicle - hard coal | AO4: Distance over Lifetime | AP4: Gas Vehicle | AQ4: Electric Vehicle - EU mix | AR4: Electric Vehicle - Wind | AS4: Electric Vehicle - Photovoltaic | AT4: Electric Vehicle - Hard coal | AV4: Distance over Lifetime | AW4: Gas Vehicle | AX4: Electric Vehicle | AY4: Electric Vehicle - Wind | AZ4: Electric Vehicle - Photovoltaic | BA4: Electric Vehicle - Hard coal
A5: Manufacturing (Materials + Processing) | O5: Car manufacturing | P5: =SUM(E6:E28) -> 0 | Q5: =SUM($E$49:$E$62) -> 0 | R5: =SUM($E$49:$E$62) -> 0 | S5: =SUM($E$49:$E$62) -> 0 | T5: =SUM($E$49:$E$62) -> 0 | V5: Car manufacturing | W5: =SUM(H6:H28) -> 0 | X5: =SUM($H$49:$H$62) -> 0 | Y5: =SUM($H$49:$H$62) -> 0 | Z5: =SUM($H$49:$H$62) -> 0 | AA5: =SUM($H$49:$H$62) -> 0 | AC5: Car manufacturing | AD5: =SUM(L6:L28) -> 0 | AF5: =SUM($L$49:$L$62) -> 0 | AH5: =SUM($L$49:$L$62) -> 0 | AJ5: =SUM($L$49:$L$62) -> 0 | AL5: =SUM($L$49:$L$62) -> 0 | AO5: 0 | AP5: =SUM(AD5:AD6)*AD3 -> 0 | AQ5: =SUM(AF5:AF6)*AF3 -> 0 | AR5: =SUM(AH5:AH6)*AH3 -> 0 | AS5: =SUM(AJ5:AJ6)*AJ3 -> 0 | AT5: =SUM(AL5:AL6)*AL3 -> 0 | AV5: 0.01 | AW5: =AP5/$AV5 -> 0 | AX5: =AQ5/$AV5 -> 0 | AY5: =AR5/$AV5 -> 0 | AZ5: =AS5/$AV5 -> 0 | BA5: =AT5/$AV5 -> 0
C6: kg | E6: =D6*$B6 -> 0 | F6: =E6/E$43 -> #DIV/0! | H6: =G6*$B6 -> 0 | I6: =H6/H$43 -> #DIV/0! | J6: =H6/E6*$B$2 -> #DIV/0! | L6: =K6*$B6 -> 0 | M6: =L6/L$43 -> #DIV/0! | O6: Car transportation | P6: =SUM(E30:E32) -> 0 | Q6: =SUM($E$64:$E$66) -> 0 | R6: =SUM($E$64:$E$66) -> 0 | S6: =SUM($E$64:$E$66) -> 0 | T6: =SUM($E$64:$E$66) -> 0 | V6: Car transportation | W6: =SUM(H30:H32) -> 0 | X6: =SUM($H$64:$H$66) -> 0 | Y6: =SUM($H$64:$H$66) -> 0 | Z6: =SUM($H$64:$H$66) -> 0 | AA6: =SUM($H$64:$H$66) -> 0 | AC6: Car transportation | AD6: =SUM(L30:L32) -> 0 | AF6: =SUM($L$64:$L$66) -> 0 | AH6: =SUM($L$64:$L$66) -> 0 | AJ6: =SUM($L$64:$L$66) -> 0 | AL6: =SUM($L$64:$L$66) -> 0 | AO6: 1000 | AP6: =AP$5+AD$8*$AO6 -> 0 | AQ6: =AQ$5+AF$9*$AO6 -> 0 | AR6: =AR$5+AH$10*$AO6 -> 0 | AS6: =AS$5+AJ$11*$AO6 -> 0 | AT6: =AT$5+AL$12*$AO6 -> 0 | AV6: =AO6 -> 1000 | AW6: =AP6/$AV6 -> 0 | AX6: =AQ6/$AV6 -> 0 | AY6: =AR6/$AV6 -> 0 | AZ6: =AS6/$AV6 -> 0 | BA6: =AT6/$AV6 -> 0
C7: kg | E7: =D7*$B7 -> 0 | F7: =E7/E$43 -> #DIV/0! | H7: =G7*$B7 -> 0 | I7: =H7/H$43 -> #DIV/0! | J7: =H7/E7*$B$2 -> #DIV/0! | L7: =K7*$B7 -> 0 | M7: =L7/L$43 -> #DIV/0! | O7: Car disposal | P7: =SUM(E37:E41) -> 0 | Q7: =SUM($E$73:$E$78) -> 0 | R7: =SUM($E$73:$E$78) -> 0 | S7: =SUM($E$73:$E$78) -> 0 | T7: =SUM($E$73:$E$78) -> 0 | V7: Car disposal | W7: =SUM(H37:H41) -> 0 | X7: =SUM($H$73:$H$78) -> 0 | Y7: =SUM($H$73:$H$78) -> 0 | Z7: =SUM($H$73:$H$78) -> 0 | AA7: =SUM($H$73:$H$78) -> 0 | AC7: Car disposal | AD7: =SUM(L37:L41) -> 0 | AF7: =SUM($L$73:$L$78) -> 0 | AH7: =SUM($L$73:$L$78) -> 0 | AJ7: =SUM($L$73:$L$78) -> 0 | AL7: =SUM($L$73:$L$78) -> 0 | AO7: 2000 | AP7: =AP$5+AD$8*$AO7 -> 0 | AQ7: =AQ$5+AF$9*$AO7 -> 0 | AR7: =AR$5+AH$10*$AO7 -> 0 | AS7: =AS$5+AJ$11*$AO7 -> 0 | AT7: =AT$5+AL$12*$AO7 -> 0 | AV7: =AO7 -> 2000 | AW7: =AP7/$AV7 -> 0 | AX7: =AQ7/$AV7 -> 0 | AY7: =AR7/$AV7 -> 0 | AZ7: =AS7/$AV7 -> 0 | BA7: =AT7/$AV7 -> 0
C8: kg | E8: =D8*$B8 -> 0 | F8: =E8/E$43 -> #DIV/0! | H8: =G8*$B8 -> 0 | I8: =H8/H$43 -> #DIV/0! | J8: =H8/E8*$B$2 -> #DIV/0! | L8: =K8*$B8 -> 0 | M8: =L8/L$43 -> #DIV/0! | O8: Petrol gas | P8: =E34 -> 0 | V8: Petrol gas | W8: =H34+H35 -> 0 | AC8: Petrol gas | AD8: =L34+L35 -> 0 | AO8: 3000 | AP8: =AP$5+AD$8*$AO8 -> 0 | AQ8: =AQ$5+AF$9*$AO8 -> 0 | AR8: =AR$5+AH$10*$AO8 -> 0 | AS8: =AS$5+AJ$11*$AO8 -> 0 | AT8: =AT$5+AL$12*$AO8 -> 0 | AV8: =AO8 -> 3000 | AW8: =AP8/$AV8 -> 0 | AX8: =AQ8/$AV8 -> 0 | AY8: =AR8/$AV8 -> 0 | AZ8: =AS8/$AV8 -> 0 | BA8: =AT8/$AV8 -> 0
C9: kg | E9: =D9*$B9 -> 0 | F9: =E9/E$43 -> #DIV/0! | H9: =G9*$B9 -> 0 | I9: =H9/H$43 -> #DIV/0! | J9: =H9/E9*$B$2 -> #DIV/0! | L9: =K9*$B9 -> 0 | M9: =L9/L$43 -> #DIV/0! | O9: Electric charging - RER | Q9: =E68 -> 0 | V9: Electric charging - RER | X9: =H68 -> 0 | AC9: Electric charging - RER | AF9: =L68 -> 0 | AO9: 5000 | AP9: =AP$5+AD$8*$AO9 -> 0 | AQ9: =AQ$5+AF$9*$AO9 -> 0 | AR9: =AR$5+AH$10*$AO9 -> 0 | AS9: =AS$5+AJ$11*$AO9 -> 0 | AT9: =AT$5+AL$12*$AO9 -> 0 | AV9: =AO9 -> 5000 | AW9: =AP9/$AV9 -> 0 | AX9: =AQ9/$AV9 -> 0 | AY9: =AR9/$AV9 -> 0 | AZ9: =AS9/$AV9 -> 0 | BA9: =AT9/$AV9 -> 0
C10: kg | E10: =D10*$B10 -> 0 | F10: =E10/E$43 -> #DIV/0! | H10: =G10*$B10 -> 0 | I10: =H10/H$43 -> #DIV/0! | J10: =H10/E10*$B$2 -> #DIV/0! | L10: =K10*$B10 -> 0 | M10: =L10/L$43 -> #DIV/0! | O10: Electric charging - wind | R10: =E69 -> 0 | V10: Electric charging - wind | Y10: =H69 -> 0 | AC10: Electric charging - wind | AH10: =L69 -> 0 | AO10: 7000 | AP10: =AP$5+AD$8*$AO10 -> 0 | AQ10: =AQ$5+AF$9*$AO10 -> 0 | AR10: =AR$5+AH$10*$AO10 -> 0 | AS10: =AS$5+AJ$11*$AO10 -> 0 | AT10: =AT$5+AL$12*$AO10 -> 0 | AV10: =AO10 -> 7000 | AW10: =AP10/$AV10 -> 0 | AX10: =AQ10/$AV10 -> 0 | AY10: =AR10/$AV10 -> 0 | AZ10: =AS10/$AV10 -> 0 | BA10: =AT10/$AV10 -> 0
C11: kg | E11: =D11*$B11 -> 0 | F11: =E11/E$43 -> #DIV/0! | H11: =G11*$B11 -> 0 | I11: =H11/H$43 -> #DIV/0! | J11: =H11/E11*$B$2 -> #DIV/0! | L11: =K11*$B11 -> 0 | M11: =L11/L$43 -> #DIV/0! | O11: Electric charging - photovoltaic | S11: =E70 -> 0 | V11: Electric charging - photovoltaic | Z11: =H70 -> 0 | AC11: Electric charging - photovoltaic | AJ11: =L70 -> 0 | AO11: 10000 | AP11: =AP$5+AD$8*$AO11 -> 0 | AQ11: =AQ$5+AF$9*$AO11 -> 0 | AR11: =AR$5+AH$10*$AO11 -> 0 | AS11: =AS$5+AJ$11*$AO11 -> 0 | AT11: =AT$5+AL$12*$AO11 -> 0 | AV11: =AO11 -> 10000 | AW11: =AP11/$AV11 -> 0 | AX11: =AQ11/$AV11 -> 0 | AY11: =AR11/$AV11 -> 0 | AZ11: =AS11/$AV11 -> 0 | BA11: =AT11/$AV11 -> 0
C12: kg | E12: =D12*$B12 -> 0 | F12: =E12/E$43 -> #DIV/0! | H12: =G12*$B12 -> 0 | I12: =H12/H$43 -> #DIV/0! | J12: =H12/E12*$B$2 -> #DIV/0! | L12: =K12*$B12 -> 0 | M12: =L12/L$43 -> #DIV/0! | O12: Electric charging - hard coal | T12: =E71 -> 0 | V12: Electric charging - hard coal | AA12: =H71 -> 0 | AC12: Electric charging - hard coal | AL12: =L71 -> 0 | AO12: 20000 | AP12: =AP$5+AD$8*$AO12 -> 0 | AQ12: =AQ$5+AF$9*$AO12 -> 0 | AR12: =AR$5+AH$10*$AO12 -> 0 | AS12: =AS$5+AJ$11*$AO12 -> 0 | AT12: =AT$5+AL$12*$AO12 -> 0 | AV12: =AO12 -> 20000 | AW12: =AP12/$AV12 -> 0 | AX12: =AQ12/$AV12 -> 0 | AY12: =AR12/$AV12 -> 0 | AZ12: =AS12/$AV12 -> 0 | BA12: =AT12/$AV12 -> 0
C13: kg | E13: =D13*$B13 -> 0 | F13: =E13/E$43 -> #DIV/0! | H13: =G13*$B13 -> 0 | I13: =H13/H$43 -> #DIV/0! | J13: =H13/E13*$B$2 -> #DIV/0! | L13: =K13*$B13 -> 0 | M13: =L13/L$43 -> #DIV/0! | O13: Net value | P13: =SUM(P5:P8) -> 0 | Q13: =SUM(Q5:Q9) -> 0 | R13: =SUM(R5:R7, R10) -> 0 | S13: =SUM(S5:S7,S11) -> 0 | T13: =SUM(T5:T7,T12) -> 0 | V13: Net value | W13: =SUM(W5:W11) -> 0 | X13: =SUM(X5:X11) -> 0 | Y13: =SUM(Y5:Y11) -> 0 | Z13: =SUM(Z5:Z11) -> 0 | AA13: =SUM(AA5:AA12) -> 0 | AC13: Net value | AD13: =SUM(AD5:AD8) -> 0 | AF13: =SUM(AF5:AF9) -> 0 | AH13: =SUM(AH5:AH7, AH10) -> 0 | AJ13: =SUM(AJ5:AJ7, AJ11) -> 0 | AL13: =SUM(AL5:AL7, AL12) -> 0 | AO13: 30000 | AP13: =AP$5+AD$8*$AO13 -> 0 | AQ13: =AQ$5+AF$9*$AO13 -> 0 | AR13: =AR$5+AH$10*$AO13 -> 0 | AS13: =AS$5+AJ$11*$AO13 -> 0 | AT13: =AT$5+AL$12*$AO13 -> 0 | AV13: =AO13 -> 30000 | AW13: =AP13/$AV13 -> 0 | AX13: =AQ13/$AV13 -> 0 | AY13: =AR13/$AV13 -> 0 | AZ13: =AS13/$AV13 -> 0 | BA13: =AT13/$AV13 -> 0
C14: kg | E14: =D14*$B14 -> 0 | F14: =E14/E$43 -> #DIV/0! | H14: =G14*$B14 -> 0 | I14: =H14/H$43 -> #DIV/0! | J14: =H14/E14*$B$2 -> #DIV/0! | L14: =K14*$B14 -> 0 | M14: =L14/L$43 -> #DIV/0! | AC14: Climate change, short term - Open LCA | AO14: 40000 | AP14: =AP$5+AD$8*$AO14 -> 0 | AQ14: =AQ$5+AF$9*$AO14 -> 0 | AR14: =AR$5+AH$10*$AO14 -> 0 | AS14: =AS$5+AJ$11*$AO14 -> 0 | AT14: =AT$5+AL$12*$AO14 -> 0 | AV14: =AO14 -> 40000 | AW14: =AP14/$AV14 -> 0 | AX14: =AQ14/$AV14 -> 0 | AY14: =AR14/$AV14 -> 0 | AZ14: =AS14/$AV14 -> 0 | BA14: =AT14/$AV14 -> 0
C15: kg | E15: =D15*$B15 -> 0 | F15: =E15/E$43 -> #DIV/0! | H15: =G15*$B15 -> 0 | I15: =H15/H$43 -> #DIV/0! | J15: =H15/E15*$B$2 -> #DIV/0! | L15: =K15*$B15 -> 0 | M15: =L15/L$43 -> #DIV/0! | AC15: from open LCA in kgCO2equ short per FU | AO15: 50000 | AP15: =AP$5+AD$8*$AO15 -> 0 | AQ15: =AQ$5+AF$9*$AO15 -> 0 | AR15: =AR$5+AH$10*$AO15 -> 0 | AS15: =AS$5+AJ$11*$AO15 -> 0 | AT15: =AT$5+AL$12*$AO15 -> 0 | AV15: =AO15 -> 50000 | AW15: =AP15/$AV15 -> 0 | AX15: =AQ15/$AV15 -> 0 | AY15: =AR15/$AV15 -> 0 | AZ15: =AS15/$AV15 -> 0 | BA15: =AT15/$AV15 -> 0
C16: v | E16: =D16*$B16 -> 0 | F16: =E16/E$43 -> #DIV/0! | H16: =G16*$B16 -> 0 | I16: =H16/H$43 -> #DIV/0! | J16: =H16/E16*$B$2 -> #DIV/0! | L16: =K16*$B16 -> 0 | M16: =L16/L$43 -> #DIV/0! | T16: =0.024/0.065/55*100 -> 0.67132867 | AO16: 60000 | AP16: =AP$5+AD$8*$AO16 -> 0 | AQ16: =AQ$5+AF$9*$AO16 -> 0 | AR16: =AR$5+AH$10*$AO16 -> 0 | AS16: =AS$5+AJ$11*$AO16 -> 0 | AT16: =AT$5+AL$12*$AO16 -> 0 | AV16: =AO16 -> 60000 | AW16: =AP16/$AV16 -> 0 | AX16: =AQ16/$AV16 -> 0 | AY16: =AR16/$AV16 -> 0 | AZ16: =AS16/$AV16 -> 0 | BA16: =AT16/$AV16 -> 0
C17: kg | E17: =D17*$B17 -> 0 | F17: =E17/E$43 -> #DIV/0! | H17: =G17*$B17 -> 0 | I17: =H17/H$43 -> #DIV/0! | J17: =H17/E17*$B$2 -> #DIV/0! | L17: =K17*$B17 -> 0 | M17: =L17/L$43 -> #DIV/0! | AO17: 70000 | AP17: =AP$5+AD$8*$AO17 -> 0 | AQ17: =AQ$5+AF$9*$AO17 -> 0 | AR17: =AR$5+AH$10*$AO17 -> 0 | AS17: =AS$5+AJ$11*$AO17 -> 0 | AT17: =AT$5+AL$12*$AO17 -> 0 | AV17: =AO17 -> 70000 | AW17: =AP17/$AV17 -> 0 | AX17: =AQ17/$AV17 -> 0 | AY17: =AR17/$AV17 -> 0 | AZ17: =AS17/$AV17 -> 0 | BA17: =AT17/$AV17 -> 0
C18: kg | E18: =D18*$B18 -> 0 | F18: =E18/E$43 -> #DIV/0! | H18: =G18*$B18 -> 0 | I18: =H18/H$43 -> #DIV/0! | J18: =H18/E18*$B$2 -> #DIV/0! | L18: =K18*$B18 -> 0 | M18: =L18/L$43 -> #DIV/0! | AO18: 80000 | AP18: =AP$5+AD$8*$AO18 -> 0 | AQ18: =AQ$5+AF$9*$AO18 -> 0 | AR18: =AR$5+AH$10*$AO18 -> 0 | AS18: =AS$5+AJ$11*$AO18 -> 0 | AT18: =AT$5+AL$12*$AO18 -> 0 | AV18: =AO18 -> 80000 | AW18: =AP18/$AV18 -> 0 | AX18: =AQ18/$AV18 -> 0 | AY18: =AR18/$AV18 -> 0 | AZ18: =AS18/$AV18 -> 0 | BA18: =AT18/$AV18 -> 0
C19: kg | E19: =D19*$B19 -> 0 | F19: =E19/E$43 -> #DIV/0! | H19: =G19*$B19 -> 0 | I19: =H19/H$43 -> #DIV/0! | J19: =H19/E19*$B$2 -> #DIV/0! | L19: =K19*$B19 -> 0 | M19: =L19/L$43 -> #DIV/0! | AO19: 90000 | AP19: =AP$5+AD$8*$AO19 -> 0 | AQ19: =AQ$5+AF$9*$AO19 -> 0 | AR19: =AR$5+AH$10*$AO19 -> 0 | AS19: =AS$5+AJ$11*$AO19 -> 0 | AT19: =AT$5+AL$12*$AO19 -> 0 | AV19: =AO19 -> 90000 | AW19: =AP19/$AV19 -> 0 | AX19: =AQ19/$AV19 -> 0 | AY19: =AR19/$AV19 -> 0 | AZ19: =AS19/$AV19 -> 0 | BA19: =AT19/$AV19 -> 0
C20: kg | E20: =D20*$B20 -> 0 | F20: =E20/E$43 -> #DIV/0! | H20: =G20*$B20 -> 0 | I20: =H20/H$43 -> #DIV/0! | J20: =H20/E20*$B$2 -> #DIV/0! | L20: =K20*$B20 -> 0 | M20: =L20/L$43 -> #DIV/0! | AO20: 100000 | AP20: =AP$5+AD$8*$AO20 -> 0 | AQ20: =AQ$5+AF$9*$AO20 -> 0 | AR20: =AR$5+AH$10*$AO20 -> 0 | AS20: =AS$5+AJ$11*$AO20 -> 0 | AT20: =AT$5+AL$12*$AO20 -> 0 | AV20: =AO20 -> 100000 | AW20: =AP20/$AV20 -> 0 | AX20: =AQ20/$AV20 -> 0 | AY20: =AR20/$AV20 -> 0 | AZ20: =AS20/$AV20 -> 0 | BA20: =AT20/$AV20 -> 0
C21: kg | E21: =D21*$B21 -> 0 | F21: =E21/E$43 -> #DIV/0! | H21: =G21*$B21 -> 0 | I21: =H21/H$43 -> #DIV/0! | J21: =H21/E21*$B$2 -> #DIV/0! | L21: =K21*$B21 -> 0 | M21: =L21/L$43 -> #DIV/0! | AO21: 110000 | AP21: =AP$5+AD$8*$AO21 -> 0 | AQ21: =AQ$5+AF$9*$AO21 -> 0 | AR21: =AR$5+AH$10*$AO21 -> 0 | AS21: =AS$5+AJ$11*$AO21 -> 0 | AT21: =AT$5+AL$12*$AO21 -> 0 | AV21: =AO21 -> 110000 | AW21: =AP21/$AV21 -> 0 | AX21: =AQ21/$AV21 -> 0 | AY21: =AR21/$AV21 -> 0 | AZ21: =AS21/$AV21 -> 0 | BA21: =AT21/$AV21 -> 0
C22: kg | E22: =D22*$B22 -> 0 | F22: =E22/E$43 -> #DIV/0! | H22: =G22*$B22 -> 0 | I22: =H22/H$43 -> #DIV/0! | J22: =H22/E22*$B$2 -> #DIV/0! | L22: =K22*$B22 -> 0 | M22: =L22/L$43 -> #DIV/0! | AO22: 120000 | AP22: =AP$5+AD$8*$AO22 -> 0 | AQ22: =AQ$5+AF$9*$AO22 -> 0 | AR22: =AR$5+AH$10*$AO22 -> 0 | AS22: =AS$5+AJ$11*$AO22 -> 0 | AT22: =AT$5+AL$12*$AO22 -> 0 | AV22: =AO22 -> 120000 | AW22: =AP22/$AV22 -> 0 | AX22: =AQ22/$AV22 -> 0 | AY22: =AR22/$AV22 -> 0 | AZ22: =AS22/$AV22 -> 0 | BA22: =AT22/$AV22 -> 0
C23: kg | E23: =D23*$B23 -> 0 | F23: =E23/E$43 -> #DIV/0! | H23: =G23*$B23 -> 0 | I23: =H23/H$43 -> #DIV/0! | J23: =H23/E23*$B$2 -> #DIV/0! | L23: =K23*$B23 -> 0 | M23: =L23/L$43 -> #DIV/0! | AO23: 130000 | AP23: =AP$5+AD$8*$AO23 -> 0 | AQ23: =AQ$5+AF$9*$AO23 -> 0 | AR23: =AR$5+AH$10*$AO23 -> 0 | AS23: =AS$5+AJ$11*$AO23 -> 0 | AT23: =AT$5+AL$12*$AO23 -> 0 | AV23: =AO23 -> 130000 | AW23: =AP23/$AV23 -> 0 | AX23: =AQ23/$AV23 -> 0 | AY23: =AR23/$AV23 -> 0 | AZ23: =AS23/$AV23 -> 0 | BA23: =AT23/$AV23 -> 0
C24: kg | E24: =D24*$B24 -> 0 | F24: =E24/E$43 -> #DIV/0! | H24: =G24*$B24 -> 0 | I24: =H24/H$43 -> #DIV/0! | J24: =H24/E24*$B$2 -> #DIV/0! | L24: =K24*$B24 -> 0 | M24: =L24/L$43 -> #DIV/0! | AO24: 140000 | AP24: =AP$5+AD$8*$AO24 -> 0 | AQ24: =AQ$5+AF$9*$AO24 -> 0 | AR24: =AR$5+AH$10*$AO24 -> 0 | AS24: =AS$5+AJ$11*$AO24 -> 0 | AT24: =AT$5+AL$12*$AO24 -> 0 | AV24: =AO24 -> 140000 | AW24: =AP24/$AV24 -> 0 | AX24: =AQ24/$AV24 -> 0 | AY24: =AR24/$AV24 -> 0 | AZ24: =AS24/$AV24 -> 0 | BA24: =AT24/$AV24 -> 0
C25: kg | E25: =D25*$B25 -> 0 | F25: =E25/E$43 -> #DIV/0! | H25: =G25*$B25 -> 0 | I25: =H25/H$43 -> #DIV/0! | J25: =H25/E25*$B$2 -> #DIV/0! | L25: =K25*$B25 -> 0 | M25: =L25/L$43 -> #DIV/0! | AO25: 150000 | AP25: =AP$5+AD$8*$AO25 -> 0 | AQ25: =AQ$5+AF$9*$AO25 -> 0 | AR25: =AR$5+AH$10*$AO25 -> 0 | AS25: =AS$5+AJ$11*$AO25 -> 0 | AT25: =AT$5+AL$12*$AO25 -> 0 | AV25: =AO25 -> 150000 | AW25: =AP25/$AV25 -> 0 | AX25: =AQ25/$AV25 -> 0 | AY25: =AR25/$AV25 -> 0 | AZ25: =AS25/$AV25 -> 0 | BA25: =AT25/$AV25 -> 0
C26: kg | E26: =D26*$B26 -> 0 | F26: =E26/E$43 -> #DIV/0! | H26: =G26*$B26 -> 0 | I26: =H26/H$43 -> #DIV/0! | J26: =H26/E26*$B$2 -> #DIV/0! | L26: =K26*$B26 -> 0 | M26: =L26/L$43 -> #DIV/0! | AO26: 160000 | AP26: =AP$5+AD$8*$AO26 -> 0 | AQ26: =AQ$5+AF$9*$AO26 -> 0 | AR26: =AR$5+AH$10*$AO26 -> 0 | AS26: =AS$5+AJ$11*$AO26 -> 0 | AT26: =AT$5+AL$12*$AO26 -> 0 | AV26: =AO26 -> 160000 | AW26: =AP26/$AV26 -> 0 | AX26: =AQ26/$AV26 -> 0 | AY26: =AR26/$AV26 -> 0 | AZ26: =AS26/$AV26 -> 0 | BA26: =AT26/$AV26 -> 0
C27: kg | E27: =D27*$B27 -> 0 | F27: =E27/E$43 -> #DIV/0! | H27: =G27*$B27 -> 0 | I27: =H27/H$43 -> #DIV/0! | J27: =H27/E27*$B$2 -> #DIV/0! | L27: =K27*$B27 -> 0 | M27: =L27/L$43 -> #DIV/0! | AO27: 170000 | AP27: =AP$5+AD$8*$AO27 -> 0 | AQ27: =AQ$5+AF$9*$AO27 -> 0 | AR27: =AR$5+AH$10*$AO27 -> 0 | AS27: =AS$5+AJ$11*$AO27 -> 0 | AT27: =AT$5+AL$12*$AO27 -> 0 | AV27: =AO27 -> 170000 | AW27: =AP27/$AV27 -> 0 | AX27: =AQ27/$AV27 -> 0 | AY27: =AR27/$AV27 -> 0 | AZ27: =AS27/$AV27 -> 0 | BA27: =AT27/$AV27 -> 0
C28: kg | E28: =D28*$B28 -> 0 | F28: =E28/E$43 -> #DIV/0! | H28: =G28*$B28 -> 0 | I28: =H28/H$43 -> #DIV/0! | J28: =H28/E28*$B$2 -> #DIV/0! | L28: =K28*$B28 -> 0 | M28: =L28/L$43 -> #DIV/0! | AO28: 180000 | AP28: =AP$5+AD$8*$AO28 -> 0 | AQ28: =AQ$5+AF$9*$AO28 -> 0 | AR28: =AR$5+AH$10*$AO28 -> 0 | AS28: =AS$5+AJ$11*$AO28 -> 0 | AT28: =AT$5+AL$12*$AO28 -> 0 | AV28: =AO28 -> 180000 | AW28: =AP28/$AV28 -> 0 | AX28: =AQ28/$AV28 -> 0 | AY28: =AR28/$AV28 -> 0 | AZ28: =AS28/$AV28 -> 0 | BA28: =AT28/$AV28 -> 0
A29: Transportation | AO29: 190000 | AP29: =AP$5+AD$8*$AO29 -> 0 | AQ29: =AQ$5+AF$9*$AO29 -> 0 | AR29: =AR$5+AH$10*$AO29 -> 0 | AS29: =AS$5+AJ$11*$AO29 -> 0 | AT29: =AT$5+AL$12*$AO29 -> 0 | AV29: =AO29 -> 190000 | AW29: =AP29/$AV29 -> 0 | AX29: =AQ29/$AV29 -> 0 | AY29: =AR29/$AV29 -> 0 | AZ29: =AS29/$AV29 -> 0 | BA29: =AT29/$AV29 -> 0
C30: t-km | E30: =D30*$B30 -> 0 | F30: =E30/E$43 -> #DIV/0! | H30: =G30*$B30 -> 0 | I30: =H30/H$43 -> #DIV/0! | J30: =H30/E30*$B$2 -> #DIV/0! | L30: =K30*$B30 -> 0 | M30: =L30/L$43 -> #DIV/0! | AO30: 200000 | AP30: =AP$5+AD$8*$AO30 -> 0 | AQ30: =AQ$5+AF$9*$AO30 -> 0 | AR30: =AR$5+AH$10*$AO30 -> 0 | AS30: =AS$5+AJ$11*$AO30 -> 0 | AT30: =AT$5+AL$12*$AO30 -> 0 | AV30: =AO30 -> 200000 | AW30: =AP30/$AV30 -> 0 | AX30: =AQ30/$AV30 -> 0 | AY30: =AR30/$AV30 -> 0 | AZ30: =AS30/$AV30 -> 0 | BA30: =AT30/$AV30 -> 0
C31: t-km | E31: =D31*$B31 -> 0 | F31: =E31/E$43 -> #DIV/0! | H31: =G31*$B31 -> 0 | I31: =H31/H$43 -> #DIV/0! | J31: =H31/E31*$B$2 -> #DIV/0! | L31: =K31*$B31 -> 0 | M31: =L31/L$43 -> #DIV/0! | AO31: 210000 | AP31: =AP$5+AD$8*$AO31 -> 0 | AQ31: =AQ$5+AF$9*$AO31 -> 0 | AR31: =AR$5+AH$10*$AO31 -> 0 | AS31: =AS$5+AJ$11*$AO31 -> 0 | AT31: =AT$5+AL$12*$AO31 -> 0 | AV31: =AO31 -> 210000 | AW31: =AP31/$AV31 -> 0 | AX31: =AQ31/$AV31 -> 0 | AY31: =AR31/$AV31 -> 0 | AZ31: =AS31/$AV31 -> 0 | BA31: =AT31/$AV31 -> 0
C32: t-km | E32: =D32*$B32 -> 0 | F32: =E32/E$43 -> #DIV/0! | H32: =G32*$B32 -> 0 | I32: =H32/H$43 -> #DIV/0! | J32: =H32/E32*$B$2 -> #DIV/0! | L32: =K32*$B32 -> 0 | M32: =L32/L$43 -> #DIV/0! | AO32: 220000 | AP32: =AP$5+AD$8*$AO32 -> 0 | AQ32: =AQ$5+AF$9*$AO32 -> 0 | AR32: =AR$5+AH$10*$AO32 -> 0 | AS32: =AS$5+AJ$11*$AO32 -> 0 | AT32: =AT$5+AL$12*$AO32 -> 0 | AV32: =AO32 -> 220000 | AW32: =AP32/$AV32 -> 0 | AX32: =AQ32/$AV32 -> 0 | AY32: =AR32/$AV32 -> 0 | AZ32: =AS32/$AV32 -> 0 | BA32: =AT32/$AV32 -> 0
A33: Use phase | AO33: 230000 | AP33: =AP$5+AD$8*$AO33 -> 0 | AQ33: =AQ$5+AF$9*$AO33 -> 0 | AR33: =AR$5+AH$10*$AO33 -> 0 | AS33: =AS$5+AJ$11*$AO33 -> 0 | AT33: =AT$5+AL$12*$AO33 -> 0 | AV33: =AO33 -> 230000 | AW33: =AP33/$AV33 -> 0 | AX33: =AQ33/$AV33 -> 0 | AY33: =AR33/$AV33 -> 0 | AZ33: =AS33/$AV33 -> 0 | BA33: =AT33/$AV33 -> 0
C34: kg | E34: =D34*$B34 -> 0 | F34: =E34/E$43 -> #DIV/0! | H34: =G34*$B34 -> 0 | I34: =H34/H$43 -> #DIV/0! | J34: =H34/E34*$B$2 -> #DIV/0! | L34: =K34*$B34 -> 0 | M34: =L34/L$43 -> #DIV/0! | AO34: 240000 | AP34: =AP$5+AD$8*$AO34 -> 0 | AQ34: =AQ$5+AF$9*$AO34 -> 0 | AR34: =AR$5+AH$10*$AO34 -> 0 | AS34: =AS$5+AJ$11*$AO34 -> 0 | AT34: =AT$5+AL$12*$AO34 -> 0 | AV34: =AO34 -> 240000 | AW34: =AP34/$AV34 -> 0 | AX34: =AQ34/$AV34 -> 0 | AY34: =AR34/$AV34 -> 0 | AZ34: =AS34/$AV34 -> 0 | BA34: =AT34/$AV34 -> 0
C35: kg | E35: =D35*$B35 -> 0 | F35: =E35/E$43 -> #DIV/0! | H35: =G35*$B35 -> 0 | I35: =H35/H$43 -> #DIV/0! | J35: =H35/E34*$B$2 -> #DIV/0! | L35: =K35*$B35 -> 0 | M35: =L35/L$43 -> #DIV/0! | AO35: 250000 | AP35: =AP$5+AD$8*$AO35 -> 0 | AQ35: =AQ$5+AF$9*$AO35 -> 0 | AR35: =AR$5+AH$10*$AO35 -> 0 | AS35: =AS$5+AJ$11*$AO35 -> 0 | AT35: =AT$5+AL$12*$AO35 -> 0 | AV35: =AO35 -> 250000 | AW35: =AP35/$AV35 -> 0 | AX35: =AQ35/$AV35 -> 0 | AY35: =AR35/$AV35 -> 0 | AZ35: =AS35/$AV35 -> 0 | BA35: =AT35/$AV35 -> 0
A36: Disposal | AO36: 260000 | AP36: =AP$5+AD$8*$AO36 -> 0 | AQ36: =AQ$5+AF$9*$AO36 -> 0 | AR36: =AR$5+AH$10*$AO36 -> 0 | AS36: =AS$5+AJ$11*$AO36 -> 0 | AT36: =AT$5+AL$12*$AO36 -> 0 | AV36: =AO36 -> 260000 | AW36: =AP36/$AV36 -> 0 | AX36: =AQ36/$AV36 -> 0 | AY36: =AR36/$AV36 -> 0 | AZ36: =AS36/$AV36 -> 0 | BA36: =AT36/$AV36 -> 0
A37: emulsion paint incineration | C37: kg | E37: =D37*$B37 -> 0 | F37: =E37/E$43 -> #DIV/0! | H37: =G37*$B37 -> 0 | I37: =H37/H$43 -> #DIV/0! | J37: =H37/E37*$B$2 -> #DIV/0! | L37: =K37*$B37 -> 0 | M37: =L37/L$43 -> #DIV/0! | AO37: 270000 | AP37: =AP$5+AD$8*$AO37 -> 0 | AQ37: =AQ$5+AF$9*$AO37 -> 0 | AR37: =AR$5+AH$10*$AO37 -> 0 | AS37: =AS$5+AJ$11*$AO37 -> 0 | AT37: =AT$5+AL$12*$AO37 -> 0 | AV37: =AO37 -> 270000 | AW37: =AP37/$AV37 -> 0 | AX37: =AQ37/$AV37 -> 0 | AY37: =AR37/$AV37 -> 0 | AZ37: =AS37/$AV37 -> 0 | BA37: =AT37/$AV37 -> 0
A38: glass incineration | C38: kg | E38: =D38*$B38 -> 0 | F38: =E38/E$43 -> #DIV/0! | H38: =G38*$B38 -> 0 | I38: =H38/H$43 -> #DIV/0! | J38: =H38/E38*$B$2 -> #DIV/0! | L38: =K38*$B38 -> 0 | M38: =L38/L$43 -> #DIV/0! | AO38: 280000 | AP38: =AP$5+AD$8*$AO38 -> 0 | AQ38: =AQ$5+AF$9*$AO38 -> 0 | AR38: =AR$5+AH$10*$AO38 -> 0 | AS38: =AS$5+AJ$11*$AO38 -> 0 | AT38: =AT$5+AL$12*$AO38 -> 0 | AV38: =AO38 -> 280000 | AW38: =AP38/$AV38 -> 0 | AX38: =AQ38/$AV38 -> 0 | AY38: =AR38/$AV38 -> 0 | AZ38: =AS38/$AV38 -> 0 | BA38: =AT38/$AV38 -> 0
A39: plastic mixture incineration | C39: kg | E39: =D39*$B39 -> 0 | F39: =E39/E$43 -> #DIV/0! | H39: =G39*$B39 -> 0 | I39: =H39/H$43 -> #DIV/0! | J39: =H39/E39*$B$2 -> #DIV/0! | L39: =K39*$B39 -> 0 | M39: =L39/L$43 -> #DIV/0! | AO39: 290000 | AP39: =AP$5+AD$8*$AO39 -> 0 | AQ39: =AQ$5+AF$9*$AO39 -> 0 | AR39: =AR$5+AH$10*$AO39 -> 0 | AS39: =AS$5+AJ$11*$AO39 -> 0 | AT39: =AT$5+AL$12*$AO39 -> 0 | AV39: =AO39 -> 290000 | AW39: =AP39/$AV39 -> 0 | AX39: =AQ39/$AV39 -> 0 | AY39: =AR39/$AV39 -> 0 | AZ39: =AS39/$AV39 -> 0 | BA39: =AT39/$AV39 -> 0
A40: zinc in car shredder residue incineration | C40: kg | E40: =D40*$B40 -> 0 | F40: =E40/E$43 -> #DIV/0! | H40: =G40*$B40 -> 0 | I40: =H40/H$43 -> #DIV/0! | J40: =H40/E40*$B$2 -> #DIV/0! | L40: =K40*$B40 -> 0 | M40: =L40/L$43 -> #DIV/0! | AO40: 300000 | AP40: =AP$5+AD$8*$AO40 -> 0 | AQ40: =AQ$5+AF$9*$AO40 -> 0 | AR40: =AR$5+AH$10*$AO40 -> 0 | AS40: =AS$5+AJ$11*$AO40 -> 0 | AT40: =AT$5+AL$12*$AO40 -> 0 | AV40: =AO40 -> 300000 | AW40: =AP40/$AV40 -> 0 | AX40: =AQ40/$AV40 -> 0 | AY40: =AR40/$AV40 -> 0 | AZ40: =AS40/$AV40 -> 0 | BA40: =AT40/$AV40 -> 0
...

Sheet Processes

Sheet Input for Students
A1: kg/t conversion factor | B1: 1000
A2: g/kg | B2: 1000
A4: Transportation by Gas Vehicle | B4: Reference Product Name | C4: Reference Product Unit
A5: Manufacturing (Materials + Processing) per Vehicule
A6: alkyd paint, white, without solvent, in 60% solution state | B6: 4.368 | C6: kg
A7: aluminium, primary, ingot | B7: 54.39 | C7: kg
A8: chromium oxide, flakes | B8: 2.52 | C8: kg
A9: sheet rolling, copper | B9: 21.21 | C9: kg
A10: electronics, for control units | B10: 6.11625 | C10: kg
A11: ethylene | B11: 19.425 | C11: kg
A12: ethylene glycol | B12: 5.04 | C12: kg
A13: flat glass, uncoated | B13: 31.605 | C13: kg
A14: heat, district or industrial, natural gas | B14: 2331 | C14: MJ
A15: lead | B15: 13.65 | C15: kg
A16: Light fuel oil, burned in furnace 1MW of greenhouse/MJ - RER | B16: 66.15 | C16: MJ
A17: nickel, class 1 | B17: 1.47 | C17: kg
... A28: electricity, medium voltage | B28: 624.16667 | C28: kWh
A29: Transportation per vehicle *Please see note in top-corner* | B29: Directly Use Numbers Below
A30: transport, freight train | B30: 0.00371 | C30: t-km
A31: transport, freight, lorry 16-32 metric ton | B31: 0.00039382 | C31: t-km
A32: transport, freight, sea, container ship | B32: 0.069333333 | C32: t-km
A33: Use phase per Vehicle-km) *Please see note in top-corner* | B33: Directly Use Numbers Below
A34: Supply chain petrol, low-sulfur | B34: 0.061904762 | C34: kg
A35: Direct combustion | B35: 0.061904762 | C35: kg
A36: Disposal Determine using given information
A37: emulsion paint incineration | C37: kg
A38: glass incineration | C38: kg
A39: plastic mixture incineration | C39: kg
A40: zinc in car shredder residue incineration | C40: kg
A41: aluminium recycling | C41: kg
A43: Transportation by Electric Vehicle | B43: Reference Product Name | C43: Reference Product Unit
A44: Manufacturing (Materials + Processing)
A45: alkyd paint, white, without solvent, in 60% solution state | C45: kg
A46: Battery, Li-ion, rechargeable, prismatic | C46: kg
A47: Copper | C47: kg
A48: Electronics, for control units | C48: kg
A49: ethylene glycol | C49: kg
A50: extruded and thermoformed plastic sheets | C50: kg
A51: flat glass, uncoated | C51: kg
A52: lubricating oil | C52: kg
...
