Workbook

Sheet Milk alternatives
A1: kg/t conversion factor | B1: 1000
A2: g/kg and m/km | B2: 1000 | AC2: Sensitivity study with travel distance | AL2: Sensitivity study with travel distance
AD3: 100 | AE3: 500 | AF3: 1000 | AG3: 2000 | AH3: 3000 | AI3: 4000 | AJ3: 900 | AM3: 100 | AN3: 500 | AO3: 1000 | AP3: 2000 | AQ3: 3000 | AR3: 4000 | AS3: 900
A4: Almond Milk FU= 0.25 L milk consumed Life Cycle stage | B4: Quantity per FU | C4: Unit | D4: Energy/Unit [MJ/Unit] | E4: Energy per FU [MJ/FU] | F4: fraction | G4: CO2/Unit [kg/unit] | H4: CO2 fossil/FU | I4: fraction2 | J4: Check g CO2/MJ | K4: CO2equ/Unit [kg/unit]2 | L4: CO2equ./FU | M4: fraction3 | O4: Energy MJ/FU | P4: Almond Milk | Q4: Dairy Milk | S4: Fossil CO2 kgCO2/FU | T4: Almond Milk | U4: Dairy Milk | W4: Global warming score kgCO2equ/FU | X4: Almond Milk | Y4: Almond milk Open LCA | Z4: Dairy Milk | AA4: Dairy Milk Open LCA | AC4: Fossil CO2 kgCO2/FU | AD4: ="Almond Milk "&AD3&" km" -> Almond Milk 100 km | AE4: ="Almond Milk "&AE3&" km" -> Almond Milk 500 km | AF4: ="Almond Milk "&AF3&" km" -> Almond Milk 1000 km | AG4: ="Almond Milk "&AG3&" km" -> Almond Milk 2000 km | AH4: ="Almond Milk "&AH3&" km" -> Almond Milk 3000 km | AI4: ="Almond Milk "&AI3&" km" -> Almond Milk 4000 km | AJ4: ="Dairy Milk "&AJ3&" km" -> Dairy Milk 900 km | AL4: Global warming score kgCO2equ/FU | AM4: ="Almond Milk "&AM3&" km" -> Almond Milk 100 km | AN4: ="Almond Milk "&AN3&" km" -> Almond Milk 500 km | AO4: ="Almond Milk "&AO3&" km" -> Almond Milk 1000 km | AP4: ="Almond Milk "&AP3&" km" -> Almond Milk 2000 km | AQ4: ="Almond Milk "&AQ3&" km" -> Almond Milk 3000 km | AR4: ="Almond Milk "&AR3&" km" -> Almond Milk 4000 km | AS4: ="Dairy Milk "&AS3&" km" -> Dairy Milk 900 km
A5: Materials | O5: Almond Milk Materials | P5: =SUM(E6:E7) -> 0 | S5: Almond Milk Materials | T5: =SUM(H6:H7) -> 0 | W5: Almond Milk Materials | X5: =SUM(L6:L7) -> 0 | AC5: Almond Milk Materials | AD5: =$AG5 -> 0 | AE5: =$AG5 -> 0 | AF5: =$AG5 -> 0 | AG5: =SUM(H6:H7) -> 0 | AH5: =$AG5 -> 0 | AI5: =$AG5 -> 0 | AL5: Almond Milk Materials | AM5: =$X5 -> 0 | AN5: =$X5 -> 0 | AO5: =$X5 -> 0 | AP5: =$X5 -> 0 | AQ5: =$X5 -> 0 | AR5: =$X5 -> 0
A6: Almond, unshelled | C6: kg | E6: =D6*$B6 -> 0 | F6: =E6/E$22 -> #DIV/0! | H6: =G6*$B6 -> 0 | I6: =H6/H$22 -> #DIV/0! | J6: =H6/E6*$B$2 -> #DIV/0! | L6: =K6*$B6 -> 0 | M6: =L6/L$22 -> #DIV/0! | O6: Almond Milk Processing | P6: =SUM(E9:E11) -> 0 | S6: Almond Milk Processing | T6: =SUM(H9:H11) -> 0 | W6: Almond Milk Processing | X6: =SUM(L9:L11) -> 0 | AC6: Almond Milk Processing | AD6: =$AG6 -> 0 | AE6: =$AG6 -> 0 | AF6: =$AG6 -> 0 | AG6: =SUM(H9:H11) -> 0 | AH6: =$AG6 -> 0 | AI6: =$AG6 -> 0 | AL6: Almond Milk Processing | AM6: =$X6 -> 0 | AN6: =$X6 -> 0 | AO6: =$X6 -> 0 | AP6: =$X6 -> 0 | AQ6: =$X6 -> 0 | AR6: =$X6 -> 0
A7: Tap water | C7: kg | E7: =D7*$B7 -> 0 | F7: =E7/E$22 -> #DIV/0! | H7: =G7*$B7 -> 0 | I7: =H7/H$22 -> #DIV/0! | J7: =H7/E7*$B$2 -> #DIV/0! | L7: =K7*$B7 -> 0 | M7: =L7/L$22 -> #DIV/0! | O7: Almond Milk Disposal | P7: =SUM(E18:E20) -> 0 | S7: Almond Milk Disposal | T7: =SUM(H18:H20) -> 0 | W7: Almond Milk Disposal | X7: =SUM(L18:L20) -> 0 | AC7: Almond Milk Disposal | AD7: =$AG7 -> 0 | AE7: =$AG7 -> 0 | AF7: =$AG7 -> 0 | AG7: =SUM(H18:H20) -> 0 | AH7: =$AG7 -> 0 | AI7: =$AG7 -> 0 | AL7: Almond Milk Disposal | AM7: =$X7 -> 0 | AN7: =$AG7 -> 0 | AO7: =$AG7 -> 0 | AP7: =SUM(Q18:Q20) -> 0 | AQ7: =$AG7 -> 0 | AR7: =$AG7 -> 0
A8: Processing & packaging | O8: Dairy Milk Materials | Q8: =E27 -> #VALUE! | S8: Dairy Milk Materials | U8: =H27 -> #VALUE! | W8: Dairy Milk Materials | Z8: =L27 -> #VALUE! | AC8: Dairy Milk Materials | AJ8: =H27 -> #VALUE! | AL8: Dairy Milk Materials | AS8: =Z8 -> #VALUE!
A9: Electricity, medium voltage | C9: kWh | E9: =D9*$B9 -> 0 | F9: =E9/E$22 -> #DIV/0! | H9: =G9*$B9 -> 0 | I9: =H9/H$22 -> #DIV/0! | J9: =H9/E9*$B$2 -> #DIV/0! | L9: =K9*$B9 -> 0 | M9: =L9/L$22 -> #DIV/0! | O9: Dairy Milk Processing | Q9: =E29 -> 0 | S9: Dairy Milk Processing | U9: =H29 -> 0 | W9: Dairy Milk Processing | Z9: =L29 -> 0 | AC9: Dairy Milk Processing | AJ9: =H29 -> 0 | AL9: Dairy Milk Processing | AS9: =Z9 -> 0
A10: Steam, in chemical industry | C10: kg | E10: =D10*$B10 -> 0 | F10: =E10/E$22 -> #DIV/0! | H10: =G10*$B10 -> 0 | I10: =H10/H$22 -> #DIV/0! | J10: =H10/E10*$B$2 -> #DIV/0! | L10: =K10*$B10 -> 0 | M10: =L10/L$22 -> #DIV/0! | O10: Dairy Milk Disposal | Q10: =E36 -> 0 | S10: Dairy Milk Disposal | U10: =H36 -> 0 | W10: Dairy Milk Disposal | Z10: =L36 -> 0 | AC10: Dairy Milk Disposal | AJ10: =H36 -> 0 | AL10: Dairy Milk Disposal | AS10: =Z10 -> 0
A11: paper production, woodfree, coated, at integrated mill | C11: kg | E11: =D11*$B11 -> 0 | F11: =E11/E$38 -> #VALUE! | H11: =G11*$B11 -> 0 | I11: =H11/H$38 -> #VALUE! | J11: =H11/E11*$B$2 -> #DIV/0! | L11: =K11*$B11 -> 0 | M11: =L11/L$38 -> #VALUE! | O11: Transportation to sale | P11: =E13 -> 0 | Q11: =E31 -> 0 | S11: Transportation to sale | T11: =H13 -> 0 | U11: =H31 -> 0 | W11: Transportation to sale | X11: =L13 -> 0 | Z11: =L31 -> 0 | AB11: =(X6+X5)/(Z9+Z8) -> #VALUE! | AC11: Transportation to sale | AD11: =AG$11*$AD3/$AG$3 -> 0 | AE11: =AG$11*$AE3/$AG$3 -> 0 | AF11: =AG$11*$AF3/$AG$3 -> 0 | AG11: =H13 -> 0 | AH11: =AG$11*$AH3/$AG$3 -> 0 | AI11: =AG$11*$AI3/$AG$3 -> 0 | AJ11: =H31 -> 0 | AL11: Transportation to sale | AM11: =$AP$11*AM3/$AP$3 -> 0 | AN11: =$AP$11*AN3/$AP$3 -> 0 | AO11: =$AP$11*AO3/$AP$3 -> 0 | AP11: =$X11 -> 0 | AQ11: =$AP$11*AQ3/$AP$3 -> 0 | AR11: =$AP$11*AR3/$AP$3 -> 0 | AS11: =Z11 -> 0
A12: Transportation | O12: Transportation consumer | P12: =E14 -> 0 | Q12: =E32 -> 0 | S12: Transportation consumer | T12: =H14 -> 0 | U12: =H32 -> 0 | W12: Transportation consumer | X12: =L14 -> 0 | Z12: =L32 -> 0 | AC12: Transportation consumer | AD12: =$AG12 -> 0 | AE12: =$AG12 -> 0 | AF12: =$AG12 -> 0 | AG12: =H14 -> 0 | AH12: =$AG12 -> 0 | AI12: =$AG12 -> 0 | AJ12: =H32 -> 0 | AL12: Transportation consumer | AM12: =$X12 -> 0 | AN12: =$X12 -> 0 | AO12: =$X12 -> 0 | AP12: =$X12 -> 0 | AQ12: =$X12 -> 0 | AR12: =$X12 -> 0 | AS12: =Z12 -> 0
A13: Milk - 2000 km truck, 16-32t | C13: t-km | E13: =D13*$B13 -> 0 | F13: =E13/E$22 -> #DIV/0! | H13: =G13*$B13 -> 0 | I13: =H13/H$22 -> #DIV/0! | J13: =H13/E13*$B$2 -> #DIV/0! | L13: =K13*$B13 -> 0 | M13: =L13/L$22 -> #DIV/0! | O13: Net value | P13: =SUM(P5:P7,P12) -> 0 | Q13: =SUM(Q8:Q12) -> #VALUE! | S13: Net value | T13: =SUM(T5:T12) -> 0 | U13: =SUM(U5:U12) -> #VALUE! | W13: Net value | AC13: Net value | AJ13: =SUM(AJ5:AJ12) -> #VALUE! | AL13: Net value | AS13: =SUM(AS5:AS12) -> #VALUE!
A14: Milk - 400 m transport, passenger car | C14: km | E14: =D14*$B14 -> 0 | F14: =E14/E$22 -> #DIV/0! | H14: =G14*$B14 -> 0 | I14: =H14/H$22 -> #DIV/0! | J14: =H14/E14*$B$2 -> #DIV/0! | L14: =K14*$B14 -> 0 | M14: =L14/L$22 -> #DIV/0!
A15: Use phase
A16: - | E16: =D16*$B16 -> 0 | F16: =E16/E$22 -> #DIV/0! | H16: =G16*$B16 -> 0 | I16: =H16/H$22 -> #DIV/0! | L16: =K16*$B16 -> 0 | M16: =L16/L$22 -> #DIV/0! | X16: Reduction on production and processing
A17: Disposal
A18: Biowaste | C18: kg | E18: =D18*$B18 -> 0 | F18: =E18/E$22 -> #DIV/0! | H18: =G18*$B18 -> 0 | I18: =H18/H$22 -> #DIV/0! | J18: =H18/E18*$B$2 -> #DIV/0! | L18: =K18*$B18 -> 0 | M18: =L18/L$22 -> #DIV/0!
A19: Wastewater | C19: m3 | E19: =D19*$B19 -> 0 | F19: =E19/E$22 -> #DIV/0! | H19: =G19*$B19 -> 0 | I19: =H19/H$22 -> #DIV/0! | J19: =H19/E19*$B$2 -> #DIV/0! | L19: =K19*$B19 -> 0 | M19: =L19/L$22 -> #DIV/0!
A20: Waste paperboard to landfill | C20: kg | E20: =D20*$B20 -> 0 | F20: =E20/E$22 -> #DIV/0! | H20: =G20*$B20 -> 0 | I20: =H20/H$22 -> #DIV/0! | J20: =H20/E20*$B$2 -> #DIV/0! | L20: =K20*$B20 -> 0 | M20: =L20/L$22 -> #DIV/0!
A21: Total | AE21: Fo almond milk
A22: Total | C22: - | E22: =SUM(E6:E20) -> 0 | F22: =E22/E$22 -> #DIV/0! | H22: =SUM(H6:H20) -> 0 | I22: =H22/H$22 -> #DIV/0! | J22: =H22/E22*$B$2 -> #DIV/0! | L22: =SUM(L6:L20) -> 0 | M22: =L22/L$22 -> #DIV/0!
A25: Dairy Milk FU= 0.25 L milk consumed Life Cycle stage | B25: Quantity per FU | C25: Unit | D25: Energy/Unit [MJ/Unit] | E25: Energy per FU [MJ/FU] | F25: fraction | G25: CO2/Unit [kg/unit] | H25: CO2/FU | I25: fraction2 | J25: Check g CO2/MJ | K25: CO2equ/Unit [kg/unit]2 | L25: CO2equ./FU | M25: fraction3
A26: Materials
A27: skimmed milk, from cow milk | B27: 34% loss | C27: kg | E27: =D27*$B27 -> #VALUE! | F27: =E27/E$38 -> #VALUE! | H27: =G27*$B27 -> #VALUE! | I27: =H27/H$38 -> #VALUE! | J27: =H27/E27*$B$2 -> #VALUE! | L27: =K27*$B27 -> #VALUE! | M27: =L27/L$38 -> #VALUE!
A28: Processing & packaging
A29: paper production, woodfree, coated, at integrated mill | C29: kg | E29: =D29*$B29 -> 0 | F29: =E29/E$38 -> #VALUE! | H29: =G29*$B29 -> 0 | I29: =H29/H$38 -> #VALUE! | J29: =H29/E29*$B$2 -> #DIV/0! | L29: =K29*$B29 -> 0 | M29: =L29/L$38 -> #VALUE!
A30: Transportation
A31: Milk - 900 km refrigerated truck 7.5-16t | C31: t-km | E31: =D31*$B31 -> 0 | F31: =E31/E$38 -> #VALUE! | H31: =G31*$B31 -> 0 | I31: =H31/H$38 -> #VALUE! | J31: =H31/E31*$B$2 -> #DIV/0! | L31: =K31*$B31 -> 0 | M31: =L31/L$38 -> #VALUE!
A32: Milk - 400 m transport, passenger car | C32: km | E32: =D32*$B32 -> 0 | F32: =E32/E$38 -> #VALUE! | H32: =G32*$B32 -> 0 | I32: =H32/H$38 -> #VALUE! | J32: =H32/E32*$B$2 -> #DIV/0! | L32: =K32*$B32 -> 0 | M32: =L32/L$38 -> #VALUE!
A33: Use phase
A34: - | E34: =D34*$B34 -> 0 | F34: =E34/E$22 -> #DIV/0! | H34: =G34*$B34 -> 0 | I34: =H34/H$22 -> #DIV/0! | L34: =K34*$B34 -> 0 | M34: =L34/L$22 -> #DIV/0!
A35: Disposal
A36: waste paperboard at landfill | C36: kg | E36: =D36*$B36 -> 0 | F36: =E36/E$38 -> #VALUE! | H36: =G36*$B36 -> 0 | I36: =H36/H$38 -> #VALUE! | J36: =H36/E36*$B$2 -> #DIV/0! | L36: =K36*$B36 -> 0 | M36: =L36/L$38 -> #VALUE!
A37: Total
A38: Total | C38: - | E38: =SUM(E27:E36) -> #VALUE! | F38: =E38/E$38 -> #VALUE! | H38: =SUM(H27:H36) -> #VALUE! | I38: =H38/H$38 -> #VALUE! | J38: =H38/E38*$B$2 -> #VALUE! | L38: =SUM(L27:L36) -> #VALUE! | M38: =L38/L$38 -> #VALUE!
A41: Result discussion
A42: 3a. Almond Milk- dominant contributions | B42: The transportation for almond milk is the dominant process with mor than 60% for energy use, fossil CO2 and CO2 eq emissions
A43: 3b.Dairy Milk- dominant contributions | B43: The skimmed milk input during the production phase is the dominant source of energy use (38%) and CO2 eq emissions (58.7%)
A44: 3c. Comparison between scenarios | B44: The almond milk scenario generates onl slightly lower environmental impacts in terms of energy use compared to the dairy milk scenario. However, the dairy milk scenario generates higher environmental impacts in terms of both fossil CO2 and carbon footprints compared to the almond milk scenario.
...

Sheet Processes
B1: conversion kg_to_g | C1: 1000 | D1: g/kg | F1: Category | G1: air | H1: fossil+nuclear+primary forest | I1: CO2 fossil/total non renewable energy | K1: climate change
