Workbook
Name avoided_μDALY_in_minutes: Example!$G$3
Name g2kg: 'Carbon footprint'!$L$3
Name Serving: 'Nutritional value'!$O$5
Name standard_100g: 'Nutritional value'!$O$6

Sheet Example
B1: Burrito (140g/serving)
A2: Dietary factor | B2: Composition d (g/serving) | C2: Dietary Risk factors DRFs (avoided μDALY/g) | D2: HENI (avoided μDALY/serving) | G2: avoided μDALY in minutes
A3: Omega-3 (seafood) | B3: ='Nutritional profile'!#REF! -> #REF! | C3: 57.09 | D3: =C3*B3 -> #REF! | G3: =365*24*60/1000000 -> 0.5256
A4: Calcium (protective) | B4: ='Nutritional profile'!#REF! -> #REF! | C4: 4.9 | D4: =C4*B4 -> #REF!
A5: Nuts and seeds | B5: ='Nutritional profile'!#REF! -> #REF! | C5: 1.83 | D5: =C5*B5 -> #REF!
A6: Fiber (from other sources) | B6: ='Nutritional profile'!#REF! -> #REF! | C6: 1.04 | D6: =C6*B6 -> #REF!
A7: PUFA | B7: ='Nutritional profile'!#REF! -> #REF! | C7: 0.66 | D7: =C7*B7 -> #REF!
A8: Whole grains | B8: ='Nutritional profile'!#REF! -> #REF! | C8: 0.45 | D8: =C8*B8 -> #REF!
A9: Fruits | B9: ='Nutritional profile'!#REF! -> #REF! | C9: 0.2 | D9: =C9*B9 -> #REF!
A10: Fiber (from fruits, vegetables, and whole grains) | B10: ='Nutritional profile'!#REF! -> #REF! | C10: 0.15 | D10: =C10*B10 -> #REF!
A11: Vegetables | B11: ='Nutritional profile'!#REF! -> #REF! | C11: 0.1 | D11: =C11*B11 -> #REF!
A12: Milk | B12: ='Nutritional profile'!#REF! -> #REF! | C12: 0.01 | D12: =C12*B12 -> #REF!
A13: SSB | B13: ='Nutritional profile'!#REF! -> #REF! | C13: -0.06 | D13: =C13*B13 -> #REF!
A14: Red meat | B14: ='Nutritional profile'!#REF! -> #REF! | C14: -0.11 | D14: =C14*B14 -> #REF!
A15: Processed meat | B15: ='Nutritional profile'!#REF! -> #REF! | C15: -1.09 | D15: =C15*B15 -> #REF!
... A19: Sodium | B19: ='Nutritional profile'!#REF! -> #REF! | C19: -7.78 | D19: =C19*B19 -> #REF!
A20: Total HENI (avoided μDALY/serving) | D20: =SUM(D3:D19) -> #REF!
A21: Total HENI (Minutes of Healthy lifetime gained/serving) | D21: =D20*avoided_μDALY_in_minutes -> #REF!

Sheet Ingredients carbon footprint
A1: Food item | B1: Life Cycle Inventory data description | C1: Database | D1: Loss and waste adjustment factor | E1: kg CO2 eq/kg | F1: Loss-Adjusted Carbon footprint (kg CO2eq/kg consumed)
A2: Cheese, cheddar | B2: Hard cheese, Emmental-style, at dairy (WFLDB 3.1)/GLO S | C2: WFLDB | D2: 1.1953144 | E2: 8.6423295 | F2: =D2*E2 -> 10.330301
A3: Refried beans | B3: beans, IP, at farm/kg/CH S | C3: ESU | D3: 1.5491173 | E3: 0.15352901 | F3: =D3*E3 -> 0.23783444
A4: Tortilla | B4: wheat flour, at plant/kg/CH S | C4: ESU | D4: 1.1430535 | E4: 0.84345521 | F4: =D4*E4 -> 0.96411439
A5: Rice, white | B5: white rice, at regional storage/kg/US S | C5: ESU | D5: 1.6960651 | E5: 4.5792294 | F5: =D5*E5 -> 7.7666713
A6: Added sodium | B6: Sodium chloride, powder {GLO}| market for | Alloc Rec, U | C6: Ecoinvent | D6: 1 | E6: 0.28905884 | F6: =D6*E6 -> 0.28905884
A7: Ground beef | B7: Beef, fresh meat, at slaughterhouse (WFLDB 3.1)/US S | C7: WFLDB | D7: 1.108156 | E7: 27.215229 | F7: =D7*E7 -> 30.15872
A8: Rice, brown | B8: brown rice organic, at farm/kg/JP S | C8: ESU | D8: 1.6960651 | E8: 3.5502412 | F8: =D8*E8 -> 6.0214403
A9: Tortilla, whole wheat | B9: wholemeal flour, wheat, at plant/kg/CH S | C9: ESU | D9: 1.1430535 | E9: 0.73689271 | F9: =D9*E9 -> 0.84230776
A10: Tortilla, Non specific | B10: Bread, from wheat flour, at plant (WFLDB 3.1)/GLO S | C10: WFLDB | D10: 1.1430535 | E10: 1.4735327 | F10: =D10*E10 -> 1.6843266
A11: Vegetable combination (green beans, broccoli, onions, mushrooms) | B11: Vegetables | C11: Meier and Christen 2012 | D11: 2.4386817 | E11: 0.37 | F11: =D11*E11 -> 0.90231223

Sheet Carbon footprint
A1: Conversion factor | B1: g/kg | C1: 1000
A3: Meat Burrito (140g/serving)
A4: Ingredients | B4: Composition | C4: gingredient/serving | D4: kg CO2 eq/kgingredient | E4: kg CO2 eq/serving | F4: Contribution
A5: Cheese, cheddar | B5: 0.067272116 | C5: =B5*C$11 -> 9.4180962 | D5: =INDEX('Ingredients carbon footprint'!$F$2:F$11,MATCH('Carbon footprint'!A5,'Ingredients carbon footprint'!$A$2:$A$11,0)) -> 10.330301 | E5: =C5*D5/$C$1 -> 0.097291765 | F5: =E5/$E$11 -> 0.06467049
A6: Refried beans | B6: 0.14463505 | C6: =B6*C$11 -> 20.248907 | D6: =INDEX('Ingredients carbon footprint'!$F$2:F$11,MATCH('Carbon footprint'!A6,'Ingredients carbon footprint'!$A$2:$A$11,0)) -> 0.23783444 | E6: =C6*D6/$C$1 -> 0.0048158874 | F6: =E6/$E$11 -> 0.0032011527
A7: Added sodium | B7: 0.0067542965 | C7: =B7*C$11 -> 0.94560152 | D7: =INDEX('Ingredients carbon footprint'!$F$2:F$11,MATCH('Carbon footprint'!A7,'Ingredients carbon footprint'!$A$2:$A$11,0)) -> 0.28905884 | E7: =C7*D7/$C$1 -> 0.00027333448 | F7: =E7/$E$11 -> 0.00018168727
A8: Tortilla | B8: 0.35317861 | C8: =B8*C$11 -> 49.445005 | D8: =INDEX('Ingredients carbon footprint'!$F$2:F$11,MATCH('Carbon footprint'!A8,'Ingredients carbon footprint'!$A$2:$A$11,0)) -> 0.96411439 | E8: =C8*D8/$C$1 -> 0.047670641 | F8: =E8/$E$11 -> 0.031686996
A9: Rice, white | B9: 0.14463505 | C9: =B9*C$11 -> 20.248907 | D9: =INDEX('Ingredients carbon footprint'!$F$2:F$11,MATCH('Carbon footprint'!A9,'Ingredients carbon footprint'!$A$2:$A$11,0)) -> 7.7666713 | E9: =C9*D9/$C$1 -> 0.1572666 | F9: =E9/$E$11 -> 0.10453617
A10: Ground beef | B10: 0.28352488 | C10: =B10*C$11 -> 39.693484 | D10: =INDEX('Ingredients carbon footprint'!$F$2:F$11,MATCH('Carbon footprint'!A10,'Ingredients carbon footprint'!$A$2:$A$11,0)) -> 30.15872 | E10: =C10*D10/$C$1 -> 1.1971046 | F10: =E10/$E$11 -> 0.79572351
A11: Total | B11: =SUM(B5:B10) -> 1 | C11: 140 | E11: =SUM(E5:E10) -> 1.5044229 | F11: =SUM(F5:F10) -> 1
A13: Veggie Burrito (140g/serving)
A14: Ingredients | B14: Composition | C14: gingredient/serving | D14: kg CO2 eq/kgingredient | E14: kg CO2 eq/serving | F14: Contribution
A15: Cheese, cheddar | B15: 0.067272116
A16: Refried beans | B16: 0.14463505
A17: Added sodium | B17: 0.0067542965
A18: Tortilla, whole wheat | B18: 0.35317861
A19: Rice, brown | B19: 0.14463505
A20: Vegetable combination (green beans, broccoli, onions, mushrooms) | B20: 0.28352488
A21: Total | B21: =SUM(B15:B20) -> 1
D22: you can either manually copy or link the value from the "ingredients carbon footprint tab and table in this column, or copy the powerful and magic index-match formula from D5 or D8 - see explanation how it works below - could be life changing if you use excel regularly
A23: Use of Index-match to find automatically a cell in a range
A24: The combination of the Index and match function in excel is a very powerful way to automatically find values in a reference table, that is not ranked in the same order than the table you are using
A25: It is more reliable than the Vlookup or Hlookup functions which do not adapt automatically if you e.g. insert a column in your reference table afterwards
A27: Step 1: return the value at a certain poition in a refrence table
A28: Index($value_range,n) return the value of the nth cell in $value_range (that must be blocked with $ since you want to keep it fixed when you copy)
A29: If you look at cell D8,
A30: " =INDEX('Ingredients carbon footprint'!$F$2:F$11,n) | D30: with n= match(…) that we will learn below
A31: it returns the nth cell in the range 'Ingredients carbon footprint'!$F$2:F$11, that t is the range $F$2:F$11 from the Ingredients carbon footprint tab. That is 0.84 kgCO2/kg
A32: which gives you what you want, i.e Loss-Adjusted Carbon footprint (kg CO2eq/kg consumed)
A34: Step 2: identify the rank n of this nth cell in the reference table.
A35: This is where we use the match function
A36: MATCH(lookup_value, $lookup_range,0) returns the relative position of the lookup_value in the $lookup_range
A37: Taking cell D8 as an example, MATCH('Carbon footprint'!A8,'Ingredients carbon footprint'!$A$2:$A$11,0) looks for the position of "tortilla" in the lookup
A38: and return the value | B38: =MATCH('Carbon footprint'!A8,'Ingredients carbon footprint'!$A$2:$A$11,0) -> 3 | C38: because "tortilla" as defined by Carbon footprint'!A8 is the third item in the table.
A39: Again, you need to block the lookup range with $ so that it does not cheng when you copy it
A40: You also add " ,0) " at the end of the match function that indicates that you want an exact match
A42: Thus =INDEX('Ingredients carbon footprint'!$F$2:F$11,3) returns the 3rd value in that table , which is 0.96
A43: When you copy this cell o the other of column D, you get automatically the right values --> saves a lot of times and mistakes with larger tables!
A45: and in addition
A46: Index can also work with an array instead of a single column range, then using two match function, one to identify the column and one to identify the row
...

Sheet Nutritional value
A1: Conversion factor | C1: Risk component composition Meat Burrito | H1: Risk component composition Veggie Burrito
A2: g/100g | B2: 100 | C2: Common to both Burritos | E2: Meat Burrito only | H2: Common to both Burritos | J2: Veggie Burrito only | P2: Minutes gained by µDALY | Q2: [min./µDALY] | R2: =-365.25*24*60/1000000 -> -0.52596
A3: Burrito composition | B3: Total | C3: Cheese, cheddar | D3: Refried beans | E3: Tortilla | F3: Rice, white | G3: Ground beef | H3: Cheese, cheddar | I3: Refried beans | J3: Tortilla, whole wheat | K3: Rice, brown | L3: Vegetable combination
A4: Percentage of ingredient (%) | B4: =SUM(C4:G4) -> 0.9932457 | C4: 0.067272116 | D4: 0.14463505 | E4: 0.35317861 | F4: 0.14463505 | G4: 0.28352488 | H4: 0.067272116 | I4: 0.14463505 | J4: 0.35317861 | K4: 0.14463505 | L4: 0.28352488
A5: Mass of each ingredient (g/burrito serving) | B5: 140 | C5: =$B5*C4 -> 9.4180962 | D5: =$B5*D4 -> 20.248907 | E5: =$B5*E4 -> 49.445005 | F5: =$B5*F4 -> 20.248907 | G5: =$B5*G4 -> 39.693484 | H5: =$B5*H4 -> 9.4180962 | I5: =$B5*I4 -> 20.248907 | J5: =$B5*J4 -> 49.445005 | ... L5: =$B5*L4 -> 39.693484 | P5: Meat Burrito (140g/burrito serving) | Q5: Profiling: dr - Risk component composition per burrito serving | W5: Dietary risk factors | X5: DANI Effect on human health for each risk component-ingredient combination per burrito serving | AC5: DANI | AE5: Veggie Burrito (140g/serving) | AF5: Profiling: dr - Risk component composition per burrito serving | AL5: Dietary risk factors | AM5: DANI Effect on human health for each risk component-ingredient combination per burrito serving | AR5: DANI
A6: Dietary factor | C6: Cheese, cheddar (g/100g) | D6: Refried beans (g/100g) | E6: Tortilla (g/100g) | F6: Rice, white (g/100g) | G6: Ground beef (g/100g) | H6: Cheese, cheddar (g/100g) | I6: Refried beans (g/100g) | J6: Tortilla, whole wheat (g/100g) | K6: Rice, brown (g/100g) | L6: Vegetable combination (g/100g) | P6: Dietary factor | Q6: Cheese, cheddar (g/serving) | R6: Refried beans (g/serving) | S6: Tortilla (g/serving) | T6: Rice, white (g/serving) | U6: Ground beef (g/serving) | V6: Total (g/serving) | W6: DRFs (μDALY/g) | X6: Cheese, cheddar ( μDALY/serving) | Y6: Refried beans ( μDALY/serving) | Z6: Tortilla ( μDALY/serving) | AA6: Rice, white ( μDALY/serving) | AB6: Ground beef ( μDALY/serving) | AC6: Total (μDALY/serving) | AE6: Dietary factor | AF6: Cheese, cheddar (g/serving) | AG6: Refried beans (g/serving) | AH6: Tortilla, whole wheat (g/serving) | AI6: Rice, brown (g/serving) | AJ6: Vegetable combination (g/serving) | AK6: Total (g/serving) | AL6: DRFs (μDALY/g) | AM6: Cheese, cheddar (μDALY/serving) | AN6: Refried beans (μDALY/serving) | AO6: Tortilla Tortilla, whole wheat (μDALY/serving) | AP6: Rice, brown ( μDALY/serving) | AQ6: Vegetable combination (μDALY/serving) | AR6: Total (μDALY/serving)
A7: Omega-3 (seafood) | C7: =_xlfn.IFNA(INDEX('Nutritional profile'!$M$3:$W$11,MATCH('Nutritional value'!C$6,'Nutritional profile'!$B$3:$B$11,0),MATCH('Nutritional value'!$B7,'Nutritional profile'!$M$2:$W$2,0)),0) -> 0 | D7: =_xlfn.IFNA(INDEX('Nutritional profile'!$M$3:$W$11,MATCH('Nutritional value'!D$6,'Nutritional profile'!$B$3:$B$11,0),MATCH('Nutritional value'!$B7,'Nutritional profile'!$M$2:$W$2,0)),0) -> 0 | E7: =_xlfn.IFNA(INDEX('Nutritional profile'!$M$3:$W$11,MATCH('Nutritional value'!E$6,'Nutritional profile'!$B$3:$B$11,0),MATCH('Nutritional value'!$B7,'Nutritional profile'!$M$2:$W$2,0)),0) -> 0 | F7: =_xlfn.IFNA(INDEX('Nutritional profile'!$M$3:$W$11,MATCH('Nutritional value'!F$6,'Nutritional profile'!$B$3:$B$11,0),MATCH('Nutritional value'!$B7,'Nutritional profile'!$M$2:$W$2,0)),0) -> 0 | G7: =_xlfn.IFNA(INDEX('Nutritional profile'!$M$3:$W$11,MATCH('Nutritional value'!G$6,'Nutritional profile'!$B$3:$B$11,0),MATCH('Nutritional value'!$B7,'Nutritional profile'!$M$2:$W$2,0)),0) -> 0 | H7: =_xlfn.IFNA(INDEX('Nutritional profile'!$M$3:$W$11,MATCH('Nutritional value'!H$6,'Nutritional profile'!$B$3:$B$11,0),MATCH('Nutritional value'!$B7,'Nutritional profile'!$M$2:$W$2,0)),0) -> 0 | I7: =_xlfn.IFNA(INDEX('Nutritional profile'!$M$3:$W$11,MATCH('Nutritional value'!I$6,'Nutritional profile'!$B$3:$B$11,0),MATCH('Nutritional value'!$B7,'Nutritional profile'!$M$2:$W$2,0)),0) -> 0 | J7: =_xlfn.IFNA(INDEX('Nutritional profile'!$M$3:$W$11,MATCH('Nutritional value'!J$6,'Nutritional profile'!$B$3:$B$11,0),MATCH('Nutritional value'!$B7,'Nutritional profile'!$M$2:$W$2,0)),0) -> 0 | ... L7: =_xlfn.IFNA(INDEX('Nutritional profile'!$M$3:$W$11,MATCH('Nutritional value'!L$6,'Nutritional profile'!$B$3:$B$11,0),MATCH('Nutritional value'!$B7,'Nutritional profile'!$M$2:$W$2,0)),0) -> 0 | N7: Omega-3 (seafood) | O7: -80.66436 | P7: Omega-3 (seafood) | Q7: =C$5*C7/$B$2 -> 0 | R7: =D$5*D7/$B$2 -> 0 | S7: =E$5*E7/$B$2 -> 0 | T7: =F$5*F7/$B$2 -> 0 | U7: =G$5*G7/$B$2 -> 0 | V7: =SUM(Q7:U7) -> 0 | W7: =$O7 -> -80.66436 | X7: =Q7*$W7 -> 0 | Y7: =R7*$W7 -> 0 | Z7: =S7*$W7 -> 0 | AA7: =T7*$W7 -> 0 | AB7: =U7*$W7 -> 0 | AC7: =SUM(X7:AB7) -> 0 | AE7: Omega-3 (seafood) | AF7: =H$5*H7/$B$2 -> 0 | AG7: =I$5*I7/$B$2 -> 0 | AH7: =J$5*J7/$B$2 -> 0 | AI7: =K$5*K7/$B$2 -> 0 | AJ7: =L$5*L7/$B$2 -> 0 | AK7: =SUM(AF7:AJ7) -> 0 | AL7: =W7 -> -80.66436 | AM7: =AF7*$AL7 -> 0 | AN7: =AG7*$AL7 -> 0 | AO7: =AH7*$AL7 -> 0 | AP7: =AI7*$AL7 -> 0 | AQ7: =AJ7*$AL7 -> 0 | AR7: =SUM(AM7:AQ7) -> 0
A8: Calcium (protective) | B8: calc | C8: =_xlfn.IFNA(INDEX('Nutritional profile'!$M$3:$W$11,MATCH('Nutritional value'!C$6,'Nutritional profile'!$B$3:$B$11,0),MATCH('Nutritional value'!$B8,'Nutritional profile'!$M$2:$W$2,0)),0) -> 0.71 | D8: =_xlfn.IFNA(INDEX('Nutritional profile'!$M$3:$W$11,MATCH('Nutritional value'!D$6,'Nutritional profile'!$B$3:$B$11,0),MATCH('Nutritional value'!$B8,'Nutritional profile'!$M$2:$W$2,0)),0) -> 0.034319769 | E8: =_xlfn.IFNA(INDEX('Nutritional profile'!$M$3:$W$11,MATCH('Nutritional value'!E$6,'Nutritional profile'!$B$3:$B$11,0),MATCH('Nutritional value'!$B8,'Nutritional profile'!$M$2:$W$2,0)),0) -> 0.146 | F8: =_xlfn.IFNA(INDEX('Nutritional profile'!$M$3:$W$11,MATCH('Nutritional value'!F$6,'Nutritional profile'!$B$3:$B$11,0),MATCH('Nutritional value'!$B8,'Nutritional profile'!$M$2:$W$2,0)),0) -> 0.010088071 | G8: =_xlfn.IFNA(INDEX('Nutritional profile'!$M$3:$W$11,MATCH('Nutritional value'!G$6,'Nutritional profile'!$B$3:$B$11,0),MATCH('Nutritional value'!$B8,'Nutritional profile'!$M$2:$W$2,0)),0) -> 0.031933412 | H8: =_xlfn.IFNA(INDEX('Nutritional profile'!$M$3:$W$11,MATCH('Nutritional value'!H$6,'Nutritional profile'!$B$3:$B$11,0),MATCH('Nutritional value'!$B8,'Nutritional profile'!$M$2:$W$2,0)),0) -> 0.71 | I8: =_xlfn.IFNA(INDEX('Nutritional profile'!$M$3:$W$11,MATCH('Nutritional value'!I$6,'Nutritional profile'!$B$3:$B$11,0),MATCH('Nutritional value'!$B8,'Nutritional profile'!$M$2:$W$2,0)),0) -> 0.034319769 | J8: =_xlfn.IFNA(INDEX('Nutritional profile'!$M$3:$W$11,MATCH('Nutritional value'!J$6,'Nutritional profile'!$B$3:$B$11,0),MATCH('Nutritional value'!$B8,'Nutritional profile'!$M$2:$W$2,0)),0) -> 0.244 | ... L8: =_xlfn.IFNA(INDEX('Nutritional profile'!$M$3:$W$11,MATCH('Nutritional value'!L$6,'Nutritional profile'!$B$3:$B$11,0),MATCH('Nutritional value'!$B8,'Nutritional profile'!$M$2:$W$2,0)),0) -> 0.024395294 | N8: Calcium | O8: -5.147637 | P8: Calcium (protective) | Q8: =C$5*C8/$B$2 -> 0.066868483 | R8: =D$5*D8/$B$2 -> 0.0069493781 | S8: =E$5*E8/$B$2 -> 0.072189707 | T8: =F$5*F8/$B$2 -> 0.0020427242 | U8: =G$5*G8/$B$2 -> 0.012675484 | V8: =SUM(Q8:U8) -> 0.16072578 | W8: =$O8 -> -5.147637 | X8: =Q8*$W8 -> -0.34421468 | Y8: =R8*$W8 -> -0.035772876 | Z8: =S8*$W8 -> -0.37160641 | AA8: =T8*$W8 -> -0.010515203 | AB8: =U8*$W8 -> -0.065248788 | AC8: =SUM(X8:AB8) -> -0.82735795 | AE8: Calcium (protective) | AF8: =H$5*H8/$B$2 -> 0.066868483 | AG8: =I$5*I8/$B$2 -> 0.0069493781 | AH8: =J$5*J8/$B$2 -> 0.12064581 | AI8: =K$5*K8/$B$2 -> 0.00062916246 | AJ8: =L$5*L8/$B$2 -> 0.0096833421 | AK8: =SUM(AF8:AJ8) -> 0.20477618 | AL8: =W8 -> -5.147637 | AM8: =AF8*$AL8 -> -0.34421468 | AN8: =AG8*$AL8 -> -0.035772876 | AO8: =AH8*$AL8 -> -0.62104085 | AP8: =AI8*$AL8 -> -0.0032387 | AQ8: =AJ8*$AL8 -> -0.04984633 | AR8: =SUM(AM8:AQ8) -> -1.0541134
A9: Nuts and seeds | C9: =_xlfn.IFNA(INDEX('Nutritional profile'!$M$3:$W$11,MATCH('Nutritional value'!C$6,'Nutritional profile'!$B$3:$B$11,0),MATCH('Nutritional value'!$B9,'Nutritional profile'!$M$2:$W$2,0)),0) -> 0 | D9: =_xlfn.IFNA(INDEX('Nutritional profile'!$M$3:$W$11,MATCH('Nutritional value'!D$6,'Nutritional profile'!$B$3:$B$11,0),MATCH('Nutritional value'!$B9,'Nutritional profile'!$M$2:$W$2,0)),0) -> 0 | E9: =_xlfn.IFNA(INDEX('Nutritional profile'!$M$3:$W$11,MATCH('Nutritional value'!E$6,'Nutritional profile'!$B$3:$B$11,0),MATCH('Nutritional value'!$B9,'Nutritional profile'!$M$2:$W$2,0)),0) -> 0 | F9: =_xlfn.IFNA(INDEX('Nutritional profile'!$M$3:$W$11,MATCH('Nutritional value'!F$6,'Nutritional profile'!$B$3:$B$11,0),MATCH('Nutritional value'!$B9,'Nutritional profile'!$M$2:$W$2,0)),0) -> 0 | G9: =_xlfn.IFNA(INDEX('Nutritional profile'!$M$3:$W$11,MATCH('Nutritional value'!G$6,'Nutritional profile'!$B$3:$B$11,0),MATCH('Nutritional value'!$B9,'Nutritional profile'!$M$2:$W$2,0)),0) -> 0 | H9: =_xlfn.IFNA(INDEX('Nutritional profile'!$M$3:$W$11,MATCH('Nutritional value'!H$6,'Nutritional profile'!$B$3:$B$11,0),MATCH('Nutritional value'!$B9,'Nutritional profile'!$M$2:$W$2,0)),0) -> 0 | I9: =_xlfn.IFNA(INDEX('Nutritional profile'!$M$3:$W$11,MATCH('Nutritional value'!I$6,'Nutritional profile'!$B$3:$B$11,0),MATCH('Nutritional value'!$B9,'Nutritional profile'!$M$2:$W$2,0)),0) -> 0 | J9: =_xlfn.IFNA(INDEX('Nutritional profile'!$M$3:$W$11,MATCH('Nutritional value'!J$6,'Nutritional profile'!$B$3:$B$11,0),MATCH('Nutritional value'!$B9,'Nutritional profile'!$M$2:$W$2,0)),0) -> 0 | ... L9: =_xlfn.IFNA(INDEX('Nutritional profile'!$M$3:$W$11,MATCH('Nutritional value'!L$6,'Nutritional profile'!$B$3:$B$11,0),MATCH('Nutritional value'!$B9,'Nutritional profile'!$M$2:$W$2,0)),0) -> 0 | N9: Nuts and seeds | O9: -1.53067 | P9: Nuts and seeds | Q9: =C$5*C9/$B$2 -> 0 | R9: =D$5*D9/$B$2 -> 0 | S9: =E$5*E9/$B$2 -> 0 | T9: =F$5*F9/$B$2 -> 0 | U9: =G$5*G9/$B$2 -> 0 | V9: =SUM(Q9:U9) -> 0 | W9: =$O9 -> -1.53067 | X9: =Q9*$W9 -> 0 | Y9: =R9*$W9 -> 0 | Z9: =S9*$W9 -> 0 | AA9: =T9*$W9 -> 0 | AB9: =U9*$W9 -> 0 | AC9: =SUM(X9:AB9) -> 0 | AE9: Nuts and seeds | AF9: =H$5*H9/$B$2 -> 0 | AG9: =I$5*I9/$B$2 -> 0 | AH9: =J$5*J9/$B$2 -> 0 | AI9: =K$5*K9/$B$2 -> 0 | AJ9: =L$5*L9/$B$2 -> 0 | AK9: =SUM(AF9:AJ9) -> 0 | AL9: =W9 -> -1.53067 | AM9: =AF9*$AL9 -> 0 | AN9: =AG9*$AL9 -> 0 | AO9: =AH9*$AL9 -> 0 | AP9: =AI9*$AL9 -> 0 | AQ9: =AJ9*$AL9 -> 0 | AR9: =SUM(AM9:AQ9) -> 0
A10: Fiber (from other sources) | B10: fiber_non_fvlw | C10: =_xlfn.IFNA(INDEX('Nutritional profile'!$M$3:$W$11,MATCH('Nutritional value'!C$6,'Nutritional profile'!$B$3:$B$11,0),MATCH('Nutritional value'!$B10,'Nutritional profile'!$M$2:$W$2,0)),0) -> 0 | D10: =_xlfn.IFNA(INDEX('Nutritional profile'!$M$3:$W$11,MATCH('Nutritional value'!D$6,'Nutritional profile'!$B$3:$B$11,0),MATCH('Nutritional value'!$B10,'Nutritional profile'!$M$2:$W$2,0)),0) -> 0 | E10: =_xlfn.IFNA(INDEX('Nutritional profile'!$M$3:$W$11,MATCH('Nutritional value'!E$6,'Nutritional profile'!$B$3:$B$11,0),MATCH('Nutritional value'!$B10,'Nutritional profile'!$M$2:$W$2,0)),0) -> 3.5 | F10: =_xlfn.IFNA(INDEX('Nutritional profile'!$M$3:$W$11,MATCH('Nutritional value'!F$6,'Nutritional profile'!$B$3:$B$11,0),MATCH('Nutritional value'!$B10,'Nutritional profile'!$M$2:$W$2,0)),0) -> 0.39748429 | G10: =_xlfn.IFNA(INDEX('Nutritional profile'!$M$3:$W$11,MATCH('Nutritional value'!G$6,'Nutritional profile'!$B$3:$B$11,0),MATCH('Nutritional value'!$B10,'Nutritional profile'!$M$2:$W$2,0)),0) -> 0 | H10: =_xlfn.IFNA(INDEX('Nutritional profile'!$M$3:$W$11,MATCH('Nutritional value'!H$6,'Nutritional profile'!$B$3:$B$11,0),MATCH('Nutritional value'!$B10,'Nutritional profile'!$M$2:$W$2,0)),0) -> 0 | I10: =_xlfn.IFNA(INDEX('Nutritional profile'!$M$3:$W$11,MATCH('Nutritional value'!I$6,'Nutritional profile'!$B$3:$B$11,0),MATCH('Nutritional value'!$B10,'Nutritional profile'!$M$2:$W$2,0)),0) -> 0 | J10: =_xlfn.IFNA(INDEX('Nutritional profile'!$M$3:$W$11,MATCH('Nutritional value'!J$6,'Nutritional profile'!$B$3:$B$11,0),MATCH('Nutritional value'!$B10,'Nutritional profile'!$M$2:$W$2,0)),0) -> 0 | ... L10: =_xlfn.IFNA(INDEX('Nutritional profile'!$M$3:$W$11,MATCH('Nutritional value'!L$6,'Nutritional profile'!$B$3:$B$11,0),MATCH('Nutritional value'!$B10,'Nutritional profile'!$M$2:$W$2,0)),0) -> 2.1349885 | N10: Fiberother | O10: -0.992536 | P10: Fiber (from other sources) | Q10: =C$5*C10/$B$2 -> 0 | R10: =D$5*D10/$B$2 -> 0 | S10: =E$5*E10/$B$2 -> 1.7305752 | T10: =F$5*F10/$B$2 -> 0.080486223 | U10: =G$5*G10/$B$2 -> 0 | V10: =SUM(Q10:U10) -> 1.8110614 | W10: =$O10 -> -0.992536 | X10: =Q10*$W10 -> 0 | Y10: =R10*$W10 -> 0 | Z10: =S10*$W10 -> -1.7176582 | AA10: =T10*$W10 -> -0.079885474 | AB10: =U10*$W10 -> 0 | AC10: =SUM(X10:AB10) -> -1.7975436 | AE10: Fiber (from other sources) | AF10: =H$5*H10/$B$2 -> 0 | AG10: =I$5*I10/$B$2 -> 0 | AH10: =J$5*J10/$B$2 -> 0 | AI10: =K$5*K10/$B$2 -> 0 | AJ10: =L$5*L10/$B$2 -> 0.8474513 | AK10: =SUM(AF10:AJ10) -> 0.8474513 | AL10: =W10 -> -0.992536 | AM10: =AF10*$AL10 -> 0 | AN10: =AG10*$AL10 -> 0 | AO10: =AH10*$AL10 -> 0 | AP10: =AI10*$AL10 -> 0 | AQ10: =AJ10*$AL10 -> -0.84112592 | AR10: =SUM(AM10:AQ10) -> -0.84112592
A11: PUFA | B11: pfat | C11: =_xlfn.IFNA(INDEX('Nutritional profile'!$M$3:$W$11,MATCH('Nutritional value'!C$6,'Nutritional profile'!$B$3:$B$11,0),MATCH('Nutritional value'!$B11,'Nutritional profile'!$M$2:$W$2,0)),0) -> 1.421 | D11: =_xlfn.IFNA(INDEX('Nutritional profile'!$M$3:$W$11,MATCH('Nutritional value'!D$6,'Nutritional profile'!$B$3:$B$11,0),MATCH('Nutritional value'!$B11,'Nutritional profile'!$M$2:$W$2,0)),0) -> 2.1324946 | E11: =_xlfn.IFNA(INDEX('Nutritional profile'!$M$3:$W$11,MATCH('Nutritional value'!E$6,'Nutritional profile'!$B$3:$B$11,0),MATCH('Nutritional value'!$B11,'Nutritional profile'!$M$2:$W$2,0)),0) -> 2.29 | F11: =_xlfn.IFNA(INDEX('Nutritional profile'!$M$3:$W$11,MATCH('Nutritional value'!F$6,'Nutritional profile'!$B$3:$B$11,0),MATCH('Nutritional value'!$B11,'Nutritional profile'!$M$2:$W$2,0)),0) -> 0.075522 | G11: =_xlfn.IFNA(INDEX('Nutritional profile'!$M$3:$W$11,MATCH('Nutritional value'!G$6,'Nutritional profile'!$B$3:$B$11,0),MATCH('Nutritional value'!$B11,'Nutritional profile'!$M$2:$W$2,0)),0) -> 0.44724318 | H11: =_xlfn.IFNA(INDEX('Nutritional profile'!$M$3:$W$11,MATCH('Nutritional value'!H$6,'Nutritional profile'!$B$3:$B$11,0),MATCH('Nutritional value'!$B11,'Nutritional profile'!$M$2:$W$2,0)),0) -> 1.421 | I11: =_xlfn.IFNA(INDEX('Nutritional profile'!$M$3:$W$11,MATCH('Nutritional value'!I$6,'Nutritional profile'!$B$3:$B$11,0),MATCH('Nutritional value'!$B11,'Nutritional profile'!$M$2:$W$2,0)),0) -> 2.1324946 | J11: =_xlfn.IFNA(INDEX('Nutritional profile'!$M$3:$W$11,MATCH('Nutritional value'!J$6,'Nutritional profile'!$B$3:$B$11,0),MATCH('Nutritional value'!$B11,'Nutritional profile'!$M$2:$W$2,0)),0) -> 0.992 | ... L11: =_xlfn.IFNA(INDEX('Nutritional profile'!$M$3:$W$11,MATCH('Nutritional value'!L$6,'Nutritional profile'!$B$3:$B$11,0),MATCH('Nutritional value'!$B11,'Nutritional profile'!$M$2:$W$2,0)),0) -> 1.0674294 | N11: Polyunsaturated fatty acids (PUFA) | O11: -0.605609 | P11: PUFA | Q11: =C$5*C11/$B$2 -> 0.13383115 | R11: =D$5*D11/$B$2 -> 0.43180685 | S11: =E$5*E11/$B$2 -> 1.1322906 | T11: =F$5*F11/$B$2 -> 0.015292379 | U11: =G$5*G11/$B$2 -> 0.1775264 | V11: =SUM(Q11:U11) -> 1.8907474 | W11: =$O11 -> -0.605609 | X11: =Q11*$W11 -> -0.081049347 | Y11: =R11*$W11 -> -0.26150611 | Z11: =S11*$W11 -> -0.68572539 | AA11: =T11*$W11 -> -0.0092612026 | AB11: =U11*$W11 -> -0.10751158 | AC11: =SUM(X11:AB11) -> -1.1450536 | AE11: PUFA | AF11: =H$5*H11/$B$2 -> 0.13383115 | AG11: =I$5*I11/$B$2 -> 0.43180685 | AH11: =J$5*J11/$B$2 -> 0.49049445 | AI11: =K$5*K11/$B$2 -> 0.07373288 | AJ11: =L$5*L11/$B$2 -> 0.42369992 | AK11: =SUM(AF11:AJ11) -> 1.5535652 | AL11: =W11 -> -0.605609 | AM11: =AF11*$AL11 -> -0.081049347 | AN11: =AG11*$AL11 -> -0.26150611 | AO11: =AH11*$AL11 -> -0.29704785 | AP11: =AI11*$AL11 -> -0.044653295 | AQ11: =AJ11*$AL11 -> -0.25659648 | AR11: =SUM(AM11:AQ11) -> -0.94085309
A12: Whole grains | B12: whole_grain | C12: =_xlfn.IFNA(INDEX('Nutritional profile'!$M$3:$W$11,MATCH('Nutritional value'!C$6,'Nutritional profile'!$B$3:$B$11,0),MATCH('Nutritional value'!$B12,'Nutritional profile'!$M$2:$W$2,0)),0) -> 0 | D12: =_xlfn.IFNA(INDEX('Nutritional profile'!$M$3:$W$11,MATCH('Nutritional value'!D$6,'Nutritional profile'!$B$3:$B$11,0),MATCH('Nutritional value'!$B12,'Nutritional profile'!$M$2:$W$2,0)),0) -> 0 | E12: =_xlfn.IFNA(INDEX('Nutritional profile'!$M$3:$W$11,MATCH('Nutritional value'!E$6,'Nutritional profile'!$B$3:$B$11,0),MATCH('Nutritional value'!$B12,'Nutritional profile'!$M$2:$W$2,0)),0) -> 0 | F12: =_xlfn.IFNA(INDEX('Nutritional profile'!$M$3:$W$11,MATCH('Nutritional value'!F$6,'Nutritional profile'!$B$3:$B$11,0),MATCH('Nutritional value'!$B12,'Nutritional profile'!$M$2:$W$2,0)),0) -> 0 | G12: =_xlfn.IFNA(INDEX('Nutritional profile'!$M$3:$W$11,MATCH('Nutritional value'!G$6,'Nutritional profile'!$B$3:$B$11,0),MATCH('Nutritional value'!$B12,'Nutritional profile'!$M$2:$W$2,0)),0) -> 0 | H12: =_xlfn.IFNA(INDEX('Nutritional profile'!$M$3:$W$11,MATCH('Nutritional value'!H$6,'Nutritional profile'!$B$3:$B$11,0),MATCH('Nutritional value'!$B12,'Nutritional profile'!$M$2:$W$2,0)),0) -> 0 | I12: =_xlfn.IFNA(INDEX('Nutritional profile'!$M$3:$W$11,MATCH('Nutritional value'!I$6,'Nutritional profile'!$B$3:$B$11,0),MATCH('Nutritional value'!$B12,'Nutritional profile'!$M$2:$W$2,0)),0) -> 0 | J12: =_xlfn.IFNA(INDEX('Nutritional profile'!$M$3:$W$11,MATCH('Nutritional value'!J$6,'Nutritional profile'!$B$3:$B$11,0),MATCH('Nutritional value'!$B12,'Nutritional profile'!$M$2:$W$2,0)),0) -> 68 | ... L12: =_xlfn.IFNA(INDEX('Nutritional profile'!$M$3:$W$11,MATCH('Nutritional value'!L$6,'Nutritional profile'!$B$3:$B$11,0),MATCH('Nutritional value'!$B12,'Nutritional profile'!$M$2:$W$2,0)),0) -> 0 | N12: Whole grains | O12: -0.344554 | P12: Whole grains | Q12: =C$5*C12/$B$2 -> 0 | R12: =D$5*D12/$B$2 -> 0 | S12: =E$5*E12/$B$2 -> 0 | T12: =F$5*F12/$B$2 -> 0 | U12: =G$5*G12/$B$2 -> 0 | V12: =SUM(Q12:U12) -> 0 | W12: =$O12 -> -0.344554 | X12: =Q12*$W12 -> 0 | Y12: =R12*$W12 -> 0 | Z12: =S12*$W12 -> 0 | AA12: =T12*$W12 -> 0 | AB12: =U12*$W12 -> 0 | AC12: =SUM(X12:AB12) -> 0 | AE12: Whole grains | AF12: =H$5*H12/$B$2 -> 0 | AG12: =I$5*I12/$B$2 -> 0 | AH12: =J$5*J12/$B$2 -> 33.622603 | AI12: =K$5*K12/$B$2 -> 6.9677573 | AJ12: =L$5*L12/$B$2 -> 0 | AK12: =SUM(AF12:AJ12) -> 40.590361 | AL12: =W12 -> -0.344554 | AM12: =AF12*$AL12 -> 0 | AN12: =AG12*$AL12 -> 0 | AO12: =AH12*$AL12 -> -11.584803 | AP12: =AI12*$AL12 -> -2.4007687 | AQ12: =AJ12*$AL12 -> 0 | AR12: =SUM(AM12:AQ12) -> -13.985571
A13: Legumes | B13: legumes | C13: =_xlfn.IFNA(INDEX('Nutritional profile'!$M$3:$W$11,MATCH('Nutritional value'!C$6,'Nutritional profile'!$B$3:$B$11,0),MATCH('Nutritional value'!$B13,'Nutritional profile'!$M$2:$W$2,0)),0) -> 0 | D13: =_xlfn.IFNA(INDEX('Nutritional profile'!$M$3:$W$11,MATCH('Nutritional value'!D$6,'Nutritional profile'!$B$3:$B$11,0),MATCH('Nutritional value'!$B13,'Nutritional profile'!$M$2:$W$2,0)),0) -> 88.053738 | E13: =_xlfn.IFNA(INDEX('Nutritional profile'!$M$3:$W$11,MATCH('Nutritional value'!E$6,'Nutritional profile'!$B$3:$B$11,0),MATCH('Nutritional value'!$B13,'Nutritional profile'!$M$2:$W$2,0)),0) -> 0 | F13: =_xlfn.IFNA(INDEX('Nutritional profile'!$M$3:$W$11,MATCH('Nutritional value'!F$6,'Nutritional profile'!$B$3:$B$11,0),MATCH('Nutritional value'!$B13,'Nutritional profile'!$M$2:$W$2,0)),0) -> 0 | G13: =_xlfn.IFNA(INDEX('Nutritional profile'!$M$3:$W$11,MATCH('Nutritional value'!G$6,'Nutritional profile'!$B$3:$B$11,0),MATCH('Nutritional value'!$B13,'Nutritional profile'!$M$2:$W$2,0)),0) -> 0 | H13: =_xlfn.IFNA(INDEX('Nutritional profile'!$M$3:$W$11,MATCH('Nutritional value'!H$6,'Nutritional profile'!$B$3:$B$11,0),MATCH('Nutritional value'!$B13,'Nutritional profile'!$M$2:$W$2,0)),0) -> 0 | I13: =_xlfn.IFNA(INDEX('Nutritional profile'!$M$3:$W$11,MATCH('Nutritional value'!I$6,'Nutritional profile'!$B$3:$B$11,0),MATCH('Nutritional value'!$B13,'Nutritional profile'!$M$2:$W$2,0)),0) -> 88.053738 | J13: =_xlfn.IFNA(INDEX('Nutritional profile'!$M$3:$W$11,MATCH('Nutritional value'!J$6,'Nutritional profile'!$B$3:$B$11,0),MATCH('Nutritional value'!$B13,'Nutritional profile'!$M$2:$W$2,0)),0) -> 0 | ... L13: =_xlfn.IFNA(INDEX('Nutritional profile'!$M$3:$W$11,MATCH('Nutritional value'!L$6,'Nutritional profile'!$B$3:$B$11,0),MATCH('Nutritional value'!$B13,'Nutritional profile'!$M$2:$W$2,0)),0) -> 0 | N13: Legumes | O13: -0.233127 | P13: Legumes | Q13: =C$5*C13/$B$2 -> 0 | R13: =D$5*D13/$B$2 -> 17.829919 | S13: =E$5*E13/$B$2 -> 0 | T13: =F$5*F13/$B$2 -> 0 | U13: =G$5*G13/$B$2 -> 0 | V13: =SUM(Q13:U13) -> 17.829919 | W13: =$O13 -> -0.233127 | X13: =Q13*$W13 -> 0 | Y13: =R13*$W13 -> -4.1566356 | Z13: =S13*$W13 -> 0 | AA13: =T13*$W13 -> 0 | AB13: =U13*$W13 -> 0 | AC13: =SUM(X13:AB13) -> -4.1566356 | AE13: Legumes | AF13: =H$5*H13/$B$2 -> 0 | AG13: =I$5*I13/$B$2 -> 17.829919 | AH13: =J$5*J13/$B$2 -> 0 | AI13: =K$5*K13/$B$2 -> 0 | AJ13: =L$5*L13/$B$2 -> 0 | AK13: =SUM(AF13:AJ13) -> 17.829919 | AL13: =W13 -> -0.233127 | AM13: =AF13*$AL13 -> 0 | AN13: =AG13*$AL13 -> -4.1566356 | AO13: =AH13*$AL13 -> 0 | AP13: =AI13*$AL13 -> 0 | AQ13: =AJ13*$AL13 -> 0 | AR13: =SUM(AM13:AQ13) -> -4.1566356
A14: Fruits | C14: =_xlfn.IFNA(INDEX('Nutritional profile'!$M$3:$W$11,MATCH('Nutritional value'!C$6,'Nutritional profile'!$B$3:$B$11,0),MATCH('Nutritional value'!$B14,'Nutritional profile'!$M$2:$W$2,0)),0) -> 0 | D14: =_xlfn.IFNA(INDEX('Nutritional profile'!$M$3:$W$11,MATCH('Nutritional value'!D$6,'Nutritional profile'!$B$3:$B$11,0),MATCH('Nutritional value'!$B14,'Nutritional profile'!$M$2:$W$2,0)),0) -> 0 | E14: =_xlfn.IFNA(INDEX('Nutritional profile'!$M$3:$W$11,MATCH('Nutritional value'!E$6,'Nutritional profile'!$B$3:$B$11,0),MATCH('Nutritional value'!$B14,'Nutritional profile'!$M$2:$W$2,0)),0) -> 0 | F14: =_xlfn.IFNA(INDEX('Nutritional profile'!$M$3:$W$11,MATCH('Nutritional value'!F$6,'Nutritional profile'!$B$3:$B$11,0),MATCH('Nutritional value'!$B14,'Nutritional profile'!$M$2:$W$2,0)),0) -> 0 | G14: =_xlfn.IFNA(INDEX('Nutritional profile'!$M$3:$W$11,MATCH('Nutritional value'!G$6,'Nutritional profile'!$B$3:$B$11,0),MATCH('Nutritional value'!$B14,'Nutritional profile'!$M$2:$W$2,0)),0) -> 0 | H14: =_xlfn.IFNA(INDEX('Nutritional profile'!$M$3:$W$11,MATCH('Nutritional value'!H$6,'Nutritional profile'!$B$3:$B$11,0),MATCH('Nutritional value'!$B14,'Nutritional profile'!$M$2:$W$2,0)),0) -> 0 | I14: =_xlfn.IFNA(INDEX('Nutritional profile'!$M$3:$W$11,MATCH('Nutritional value'!I$6,'Nutritional profile'!$B$3:$B$11,0),MATCH('Nutritional value'!$B14,'Nutritional profile'!$M$2:$W$2,0)),0) -> 0 | J14: =_xlfn.IFNA(INDEX('Nutritional profile'!$M$3:$W$11,MATCH('Nutritional value'!J$6,'Nutritional profile'!$B$3:$B$11,0),MATCH('Nutritional value'!$B14,'Nutritional profile'!$M$2:$W$2,0)),0) -> 0 | ... L14: =_xlfn.IFNA(INDEX('Nutritional profile'!$M$3:$W$11,MATCH('Nutritional value'!L$6,'Nutritional profile'!$B$3:$B$11,0),MATCH('Nutritional value'!$B14,'Nutritional profile'!$M$2:$W$2,0)),0) -> 0 | N14: Fruits | O14: -0.186999 | P14: Fruits | Q14: =C$5*C14/$B$2 -> 0 | R14: =D$5*D14/$B$2 -> 0 | S14: =E$5*E14/$B$2 -> 0 | T14: =F$5*F14/$B$2 -> 0 | U14: =G$5*G14/$B$2 -> 0 | V14: =SUM(Q14:U14) -> 0 | W14: =$O14 -> -0.186999 | X14: =Q14*$W14 -> 0 | Y14: =R14*$W14 -> 0 | Z14: =S14*$W14 -> 0 | AA14: =T14*$W14 -> 0 | AB14: =U14*$W14 -> 0 | AC14: =SUM(X14:AB14) -> 0 | AE14: Fruits | AF14: =H$5*H14/$B$2 -> 0 | AG14: =I$5*I14/$B$2 -> 0 | AH14: =J$5*J14/$B$2 -> 0 | AI14: =K$5*K14/$B$2 -> 0 | AJ14: =L$5*L14/$B$2 -> 0 | AK14: =SUM(AF14:AJ14) -> 0 | AL14: =W14 -> -0.186999 | AM14: =AF14*$AL14 -> 0 | AN14: =AG14*$AL14 -> 0 | AO14: =AH14*$AL14 -> 0 | AP14: =AI14*$AL14 -> 0 | AQ14: =AJ14*$AL14 -> 0 | AR14: =SUM(AM14:AQ14) -> 0
A15: Fiber (from fruits, vegetables, and whole grains) | B15: fiber_fvlw | C15: =_xlfn.IFNA(INDEX('Nutritional profile'!$M$3:$W$11,MATCH('Nutritional value'!C$6,'Nutritional profile'!$B$3:$B$11,0),MATCH('Nutritional value'!$B15,'Nutritional profile'!$M$2:$W$2,0)),0) -> 0 | D15: =_xlfn.IFNA(INDEX('Nutritional profile'!$M$3:$W$11,MATCH('Nutritional value'!D$6,'Nutritional profile'!$B$3:$B$11,0),MATCH('Nutritional value'!$B15,'Nutritional profile'!$M$2:$W$2,0)),0) -> 5.2619278 | E15: =_xlfn.IFNA(INDEX('Nutritional profile'!$M$3:$W$11,MATCH('Nutritional value'!E$6,'Nutritional profile'!$B$3:$B$11,0),MATCH('Nutritional value'!$B15,'Nutritional profile'!$M$2:$W$2,0)),0) -> 0 | F15: =_xlfn.IFNA(INDEX('Nutritional profile'!$M$3:$W$11,MATCH('Nutritional value'!F$6,'Nutritional profile'!$B$3:$B$11,0),MATCH('Nutritional value'!$B15,'Nutritional profile'!$M$2:$W$2,0)),0) -> 5.5514286e-17 | G15: =_xlfn.IFNA(INDEX('Nutritional profile'!$M$3:$W$11,MATCH('Nutritional value'!G$6,'Nutritional profile'!$B$3:$B$11,0),MATCH('Nutritional value'!$B15,'Nutritional profile'!$M$2:$W$2,0)),0) -> 0 | H15: =_xlfn.IFNA(INDEX('Nutritional profile'!$M$3:$W$11,MATCH('Nutritional value'!H$6,'Nutritional profile'!$B$3:$B$11,0),MATCH('Nutritional value'!$B15,'Nutritional profile'!$M$2:$W$2,0)),0) -> 0 | I15: =_xlfn.IFNA(INDEX('Nutritional profile'!$M$3:$W$11,MATCH('Nutritional value'!I$6,'Nutritional profile'!$B$3:$B$11,0),MATCH('Nutritional value'!$B15,'Nutritional profile'!$M$2:$W$2,0)),0) -> 5.2619278 | J15: =_xlfn.IFNA(INDEX('Nutritional profile'!$M$3:$W$11,MATCH('Nutritional value'!J$6,'Nutritional profile'!$B$3:$B$11,0),MATCH('Nutritional value'!$B15,'Nutritional profile'!$M$2:$W$2,0)),0) -> 9.8 | ... L15: =_xlfn.IFNA(INDEX('Nutritional profile'!$M$3:$W$11,MATCH('Nutritional value'!L$6,'Nutritional profile'!$B$3:$B$11,0),MATCH('Nutritional value'!$B15,'Nutritional profile'!$M$2:$W$2,0)),0) -> 2.1349885 | N15: Fiberf,v,l,w | O15: -0.177918 | P15: Fiber (from fruits, vegetables, and whole grains) | Q15: =C$5*C15/$B$2 -> 0 | R15: =D$5*D15/$B$2 -> 1.0654829 | S15: =E$5*E15/$B$2 -> 0 | T15: =F$5*F15/$B$2 -> 1.1241036e-17 | U15: =G$5*G15/$B$2 -> 0 | V15: =SUM(Q15:U15) -> 1.0654829 | W15: =$O15 -> -0.177918 | X15: =Q15*$W15 -> 0 | Y15: =R15*$W15 -> -0.18956858 | Z15: =S15*$W15 -> 0 | AA15: =T15*$W15 -> -1.9999826e-18 | AB15: =U15*$W15 -> 0 | AC15: =SUM(X15:AB15) -> -0.18956858 | AE15: Fiber (from fruits, vegetables, and whole grains) | AF15: =H$5*H15/$B$2 -> 0 | AG15: =I$5*I15/$B$2 -> 1.0654829 | AH15: =J$5*J15/$B$2 -> 4.8456105 | AI15: =K$5*K15/$B$2 -> 0.32232953 | AJ15: =L$5*L15/$B$2 -> 0.8474513 | AK15: =SUM(AF15:AJ15) -> 7.0808742 | AL15: =W15 -> -0.177918 | AM15: =AF15*$AL15 -> 0 | AN15: =AG15*$AL15 -> -0.18956858 | AO15: =AH15*$AL15 -> -0.86212133 | AP15: =AI15*$AL15 -> -0.057348226 | AQ15: =AJ15*$AL15 -> -0.15077684 | AR15: =SUM(AM15:AQ15) -> -1.259815
A16: Vegetables | B16: vegetable | C16: =_xlfn.IFNA(INDEX('Nutritional profile'!$M$3:$W$11,MATCH('Nutritional value'!C$6,'Nutritional profile'!$B$3:$B$11,0),MATCH('Nutritional value'!$B16,'Nutritional profile'!$M$2:$W$2,0)),0) -> 0 | D16: =_xlfn.IFNA(INDEX('Nutritional profile'!$M$3:$W$11,MATCH('Nutritional value'!D$6,'Nutritional profile'!$B$3:$B$11,0),MATCH('Nutritional value'!$B16,'Nutritional profile'!$M$2:$W$2,0)),0) -> 7.1475153 | E16: =_xlfn.IFNA(INDEX('Nutritional profile'!$M$3:$W$11,MATCH('Nutritional value'!E$6,'Nutritional profile'!$B$3:$B$11,0),MATCH('Nutritional value'!$B16,'Nutritional profile'!$M$2:$W$2,0)),0) -> 0 | F16: =_xlfn.IFNA(INDEX('Nutritional profile'!$M$3:$W$11,MATCH('Nutritional value'!F$6,'Nutritional profile'!$B$3:$B$11,0),MATCH('Nutritional value'!$B16,'Nutritional profile'!$M$2:$W$2,0)),0) -> 0 | G16: =_xlfn.IFNA(INDEX('Nutritional profile'!$M$3:$W$11,MATCH('Nutritional value'!G$6,'Nutritional profile'!$B$3:$B$11,0),MATCH('Nutritional value'!$B16,'Nutritional profile'!$M$2:$W$2,0)),0) -> 0 | H16: =_xlfn.IFNA(INDEX('Nutritional profile'!$M$3:$W$11,MATCH('Nutritional value'!H$6,'Nutritional profile'!$B$3:$B$11,0),MATCH('Nutritional value'!$B16,'Nutritional profile'!$M$2:$W$2,0)),0) -> 0 | I16: =_xlfn.IFNA(INDEX('Nutritional profile'!$M$3:$W$11,MATCH('Nutritional value'!I$6,'Nutritional profile'!$B$3:$B$11,0),MATCH('Nutritional value'!$B16,'Nutritional profile'!$M$2:$W$2,0)),0) -> 7.1475153 | J16: =_xlfn.IFNA(INDEX('Nutritional profile'!$M$3:$W$11,MATCH('Nutritional value'!J$6,'Nutritional profile'!$B$3:$B$11,0),MATCH('Nutritional value'!$B16,'Nutritional profile'!$M$2:$W$2,0)),0) -> 0 | ... L16: =_xlfn.IFNA(INDEX('Nutritional profile'!$M$3:$W$11,MATCH('Nutritional value'!L$6,'Nutritional profile'!$B$3:$B$11,0),MATCH('Nutritional value'!$B16,'Nutritional profile'!$M$2:$W$2,0)),0) -> 48.522465 | N16: Vegetables | O16: -0.082939 | P16: Vegetables | Q16: =C$5*C16/$B$2 -> 0 | R16: =D$5*D16/$B$2 -> 1.4472937 | S16: =E$5*E16/$B$2 -> 0 | T16: =F$5*F16/$B$2 -> 0 | U16: =G$5*G16/$B$2 -> 0 | V16: =SUM(Q16:U16) -> 1.4472937 | W16: =$O16 -> -0.082939 | X16: =Q16*$W16 -> 0 | Y16: =R16*$W16 -> -0.12003709 | Z16: =S16*$W16 -> 0 | AA16: =T16*$W16 -> 0 | AB16: =U16*$W16 -> 0 | AC16: =SUM(X16:AB16) -> -0.12003709 | AE16: Vegetables | AF16: =H$5*H16/$B$2 -> 0 | AG16: =I$5*I16/$B$2 -> 1.4472937 | AH16: =J$5*J16/$B$2 -> 0 | AI16: =K$5*K16/$B$2 -> 0 | AJ16: =L$5*L16/$B$2 -> 19.260257 | AK16: =SUM(AF16:AJ16) -> 20.70755 | AL16: =W16 -> -0.082939 | AM16: =AF16*$AL16 -> 0 | AN16: =AG16*$AL16 -> -0.12003709 | AO16: =AH16*$AL16 -> 0 | AP16: =AI16*$AL16 -> 0 | AQ16: =AJ16*$AL16 -> -1.5974264 | AR16: =SUM(AM16:AQ16) -> -1.7174635
A17: Milk | C17: =_xlfn.IFNA(INDEX('Nutritional profile'!$M$3:$W$11,MATCH('Nutritional value'!C$6,'Nutritional profile'!$B$3:$B$11,0),MATCH('Nutritional value'!$B17,'Nutritional profile'!$M$2:$W$2,0)),0) -> 0 | D17: =_xlfn.IFNA(INDEX('Nutritional profile'!$M$3:$W$11,MATCH('Nutritional value'!D$6,'Nutritional profile'!$B$3:$B$11,0),MATCH('Nutritional value'!$B17,'Nutritional profile'!$M$2:$W$2,0)),0) -> 0 | E17: =_xlfn.IFNA(INDEX('Nutritional profile'!$M$3:$W$11,MATCH('Nutritional value'!E$6,'Nutritional profile'!$B$3:$B$11,0),MATCH('Nutritional value'!$B17,'Nutritional profile'!$M$2:$W$2,0)),0) -> 0 | F17: =_xlfn.IFNA(INDEX('Nutritional profile'!$M$3:$W$11,MATCH('Nutritional value'!F$6,'Nutritional profile'!$B$3:$B$11,0),MATCH('Nutritional value'!$B17,'Nutritional profile'!$M$2:$W$2,0)),0) -> 0 | G17: =_xlfn.IFNA(INDEX('Nutritional profile'!$M$3:$W$11,MATCH('Nutritional value'!G$6,'Nutritional profile'!$B$3:$B$11,0),MATCH('Nutritional value'!$B17,'Nutritional profile'!$M$2:$W$2,0)),0) -> 0 | H17: =_xlfn.IFNA(INDEX('Nutritional profile'!$M$3:$W$11,MATCH('Nutritional value'!H$6,'Nutritional profile'!$B$3:$B$11,0),MATCH('Nutritional value'!$B17,'Nutritional profile'!$M$2:$W$2,0)),0) -> 0 | I17: =_xlfn.IFNA(INDEX('Nutritional profile'!$M$3:$W$11,MATCH('Nutritional value'!I$6,'Nutritional profile'!$B$3:$B$11,0),MATCH('Nutritional value'!$B17,'Nutritional profile'!$M$2:$W$2,0)),0) -> 0 | J17: =_xlfn.IFNA(INDEX('Nutritional profile'!$M$3:$W$11,MATCH('Nutritional value'!J$6,'Nutritional profile'!$B$3:$B$11,0),MATCH('Nutritional value'!$B17,'Nutritional profile'!$M$2:$W$2,0)),0) -> 0 | ... L17: =_xlfn.IFNA(INDEX('Nutritional profile'!$M$3:$W$11,MATCH('Nutritional value'!L$6,'Nutritional profile'!$B$3:$B$11,0),MATCH('Nutritional value'!$B17,'Nutritional profile'!$M$2:$W$2,0)),0) -> 0 | N17: Milk | O17: -0.007682 | P17: Milk | Q17: =C$5*C17/$B$2 -> 0 | R17: =D$5*D17/$B$2 -> 0 | S17: =E$5*E17/$B$2 -> 0 | T17: =F$5*F17/$B$2 -> 0 | U17: =G$5*G17/$B$2 -> 0 | V17: =SUM(Q17:U17) -> 0 | W17: =$O17 -> -0.007682 | X17: =Q17*$W17 -> 0 | Y17: =R17*$W17 -> 0 | Z17: =S17*$W17 -> 0 | AA17: =T17*$W17 -> 0 | AB17: =U17*$W17 -> 0 | AC17: =SUM(X17:AB17) -> 0 | AE17: Milk | AF17: =H$5*H17/$B$2 -> 0 | AG17: =I$5*I17/$B$2 -> 0 | AH17: =J$5*J17/$B$2 -> 0 | AI17: =K$5*K17/$B$2 -> 0 | AJ17: =L$5*L17/$B$2 -> 0 | AK17: =SUM(AF17:AJ17) -> 0 | AL17: =W17 -> -0.007682 | AM17: =AF17*$AL17 -> 0 | AN17: =AG17*$AL17 -> 0 | AO17: =AH17*$AL17 -> 0 | AP17: =AI17*$AL17 -> 0 | AQ17: =AJ17*$AL17 -> 0 | AR17: =SUM(AM17:AQ17) -> 0
A18: SSB | C18: =_xlfn.IFNA(INDEX('Nutritional profile'!$M$3:$W$11,MATCH('Nutritional value'!C$6,'Nutritional profile'!$B$3:$B$11,0),MATCH('Nutritional value'!$B18,'Nutritional profile'!$M$2:$W$2,0)),0) -> 0 | D18: =_xlfn.IFNA(INDEX('Nutritional profile'!$M$3:$W$11,MATCH('Nutritional value'!D$6,'Nutritional profile'!$B$3:$B$11,0),MATCH('Nutritional value'!$B18,'Nutritional profile'!$M$2:$W$2,0)),0) -> 0 | E18: =_xlfn.IFNA(INDEX('Nutritional profile'!$M$3:$W$11,MATCH('Nutritional value'!E$6,'Nutritional profile'!$B$3:$B$11,0),MATCH('Nutritional value'!$B18,'Nutritional profile'!$M$2:$W$2,0)),0) -> 0 | F18: =_xlfn.IFNA(INDEX('Nutritional profile'!$M$3:$W$11,MATCH('Nutritional value'!F$6,'Nutritional profile'!$B$3:$B$11,0),MATCH('Nutritional value'!$B18,'Nutritional profile'!$M$2:$W$2,0)),0) -> 0 | G18: =_xlfn.IFNA(INDEX('Nutritional profile'!$M$3:$W$11,MATCH('Nutritional value'!G$6,'Nutritional profile'!$B$3:$B$11,0),MATCH('Nutritional value'!$B18,'Nutritional profile'!$M$2:$W$2,0)),0) -> 0 | H18: =_xlfn.IFNA(INDEX('Nutritional profile'!$M$3:$W$11,MATCH('Nutritional value'!H$6,'Nutritional profile'!$B$3:$B$11,0),MATCH('Nutritional value'!$B18,'Nutritional profile'!$M$2:$W$2,0)),0) -> 0 | I18: =_xlfn.IFNA(INDEX('Nutritional profile'!$M$3:$W$11,MATCH('Nutritional value'!I$6,'Nutritional profile'!$B$3:$B$11,0),MATCH('Nutritional value'!$B18,'Nutritional profile'!$M$2:$W$2,0)),0) -> 0 | J18: =_xlfn.IFNA(INDEX('Nutritional profile'!$M$3:$W$11,MATCH('Nutritional value'!J$6,'Nutritional profile'!$B$3:$B$11,0),MATCH('Nutritional value'!$B18,'Nutritional profile'!$M$2:$W$2,0)),0) -> 0 | ... L18: =_xlfn.IFNA(INDEX('Nutritional profile'!$M$3:$W$11,MATCH('Nutritional value'!L$6,'Nutritional profile'!$B$3:$B$11,0),MATCH('Nutritional value'!$B18,'Nutritional profile'!$M$2:$W$2,0)),0) -> 0 | N18: Sugar-sweetened beverages (SSB) | O18: 0.0655868 | P18: SSB | Q18: =C$5*C18/$B$2 -> 0 | R18: =D$5*D18/$B$2 -> 0 | S18: =E$5*E18/$B$2 -> 0 | T18: =F$5*F18/$B$2 -> 0 | U18: =G$5*G18/$B$2 -> 0 | V18: =SUM(Q18:U18) -> 0 | W18: =$O18 -> 0.0655868 | X18: =Q18*$W18 -> 0 | Y18: =R18*$W18 -> 0 | Z18: =S18*$W18 -> 0 | AA18: =T18*$W18 -> 0 | AB18: =U18*$W18 -> 0 | AC18: =SUM(X18:AB18) -> 0 | AE18: SSB | AF18: =H$5*H18/$B$2 -> 0 | AG18: =I$5*I18/$B$2 -> 0 | AH18: =J$5*J18/$B$2 -> 0 | AI18: =K$5*K18/$B$2 -> 0 | AJ18: =L$5*L18/$B$2 -> 0 | AK18: =SUM(AF18:AJ18) -> 0 | AL18: =W18 -> 0.0655868 | AM18: =AF18*$AL18 -> 0 | AN18: =AG18*$AL18 -> 0 | AO18: =AH18*$AL18 -> 0 | AP18: =AI18*$AL18 -> 0 | AQ18: =AJ18*$AL18 -> 0 | AR18: =SUM(AM18:AQ18) -> 0
A19: Red meat | B19: red_meat | C19: =_xlfn.IFNA(INDEX('Nutritional profile'!$M$3:$W$11,MATCH('Nutritional value'!C$6,'Nutritional profile'!$B$3:$B$11,0),MATCH('Nutritional value'!$B19,'Nutritional profile'!$M$2:$W$2,0)),0) -> 0 | D19: =_xlfn.IFNA(INDEX('Nutritional profile'!$M$3:$W$11,MATCH('Nutritional value'!D$6,'Nutritional profile'!$B$3:$B$11,0),MATCH('Nutritional value'!$B19,'Nutritional profile'!$M$2:$W$2,0)),0) -> 0 | E19: =_xlfn.IFNA(INDEX('Nutritional profile'!$M$3:$W$11,MATCH('Nutritional value'!E$6,'Nutritional profile'!$B$3:$B$11,0),MATCH('Nutritional value'!$B19,'Nutritional profile'!$M$2:$W$2,0)),0) -> 0 | F19: =_xlfn.IFNA(INDEX('Nutritional profile'!$M$3:$W$11,MATCH('Nutritional value'!F$6,'Nutritional profile'!$B$3:$B$11,0),MATCH('Nutritional value'!$B19,'Nutritional profile'!$M$2:$W$2,0)),0) -> 0 | G19: =_xlfn.IFNA(INDEX('Nutritional profile'!$M$3:$W$11,MATCH('Nutritional value'!G$6,'Nutritional profile'!$B$3:$B$11,0),MATCH('Nutritional value'!$B19,'Nutritional profile'!$M$2:$W$2,0)),0) -> 91.369992 | H19: =_xlfn.IFNA(INDEX('Nutritional profile'!$M$3:$W$11,MATCH('Nutritional value'!H$6,'Nutritional profile'!$B$3:$B$11,0),MATCH('Nutritional value'!$B19,'Nutritional profile'!$M$2:$W$2,0)),0) -> 0 | I19: =_xlfn.IFNA(INDEX('Nutritional profile'!$M$3:$W$11,MATCH('Nutritional value'!I$6,'Nutritional profile'!$B$3:$B$11,0),MATCH('Nutritional value'!$B19,'Nutritional profile'!$M$2:$W$2,0)),0) -> 0 | J19: =_xlfn.IFNA(INDEX('Nutritional profile'!$M$3:$W$11,MATCH('Nutritional value'!J$6,'Nutritional profile'!$B$3:$B$11,0),MATCH('Nutritional value'!$B19,'Nutritional profile'!$M$2:$W$2,0)),0) -> 0 | ... L19: =_xlfn.IFNA(INDEX('Nutritional profile'!$M$3:$W$11,MATCH('Nutritional value'!L$6,'Nutritional profile'!$B$3:$B$11,0),MATCH('Nutritional value'!$B19,'Nutritional profile'!$M$2:$W$2,0)),0) -> 0 | N19: Red meat | O19: 0.0991487 | P19: Red meat | Q19: =C$5*C19/$B$2 -> 0 | R19: =D$5*D19/$B$2 -> 0 | S19: =E$5*E19/$B$2 -> 0 | T19: =F$5*F19/$B$2 -> 0 | U19: =G$5*G19/$B$2 -> 36.267933 | V19: =SUM(Q19:U19) -> 36.267933 | W19: =$O19 -> 0.0991487 | X19: =Q19*$W19 -> 0 | Y19: =R19*$W19 -> 0 | Z19: =S19*$W19 -> 0 | AA19: =T19*$W19 -> 0 | AB19: =U19*$W19 -> 3.5959184 | AC19: =SUM(X19:AB19) -> 3.5959184 | AE19: Red meat | AF19: =H$5*H19/$B$2 -> 0 | AG19: =I$5*I19/$B$2 -> 0 | AH19: =J$5*J19/$B$2 -> 0 | AI19: =K$5*K19/$B$2 -> 0 | AJ19: =L$5*L19/$B$2 -> 0 | AK19: =SUM(AF19:AJ19) -> 0 | AL19: =W19 -> 0.0991487 | AM19: =AF19*$AL19 -> 0 | AN19: =AG19*$AL19 -> 0 | AO19: =AH19*$AL19 -> 0 | AP19: =AI19*$AL19 -> 0 | AQ19: =AJ19*$AL19 -> 0 | AR19: =SUM(AM19:AQ19) -> 0
A20: Processed meat | C20: =_xlfn.IFNA(INDEX('Nutritional profile'!$M$3:$W$11,MATCH('Nutritional value'!C$6,'Nutritional profile'!$B$3:$B$11,0),MATCH('Nutritional value'!$B20,'Nutritional profile'!$M$2:$W$2,0)),0) -> 0 | D20: =_xlfn.IFNA(INDEX('Nutritional profile'!$M$3:$W$11,MATCH('Nutritional value'!D$6,'Nutritional profile'!$B$3:$B$11,0),MATCH('Nutritional value'!$B20,'Nutritional profile'!$M$2:$W$2,0)),0) -> 0 | E20: =_xlfn.IFNA(INDEX('Nutritional profile'!$M$3:$W$11,MATCH('Nutritional value'!E$6,'Nutritional profile'!$B$3:$B$11,0),MATCH('Nutritional value'!$B20,'Nutritional profile'!$M$2:$W$2,0)),0) -> 0 | F20: =_xlfn.IFNA(INDEX('Nutritional profile'!$M$3:$W$11,MATCH('Nutritional value'!F$6,'Nutritional profile'!$B$3:$B$11,0),MATCH('Nutritional value'!$B20,'Nutritional profile'!$M$2:$W$2,0)),0) -> 0 | G20: =_xlfn.IFNA(INDEX('Nutritional profile'!$M$3:$W$11,MATCH('Nutritional value'!G$6,'Nutritional profile'!$B$3:$B$11,0),MATCH('Nutritional value'!$B20,'Nutritional profile'!$M$2:$W$2,0)),0) -> 0 | H20: =_xlfn.IFNA(INDEX('Nutritional profile'!$M$3:$W$11,MATCH('Nutritional value'!H$6,'Nutritional profile'!$B$3:$B$11,0),MATCH('Nutritional value'!$B20,'Nutritional profile'!$M$2:$W$2,0)),0) -> 0 | I20: =_xlfn.IFNA(INDEX('Nutritional profile'!$M$3:$W$11,MATCH('Nutritional value'!I$6,'Nutritional profile'!$B$3:$B$11,0),MATCH('Nutritional value'!$B20,'Nutritional profile'!$M$2:$W$2,0)),0) -> 0 | J20: =_xlfn.IFNA(INDEX('Nutritional profile'!$M$3:$W$11,MATCH('Nutritional value'!J$6,'Nutritional profile'!$B$3:$B$11,0),MATCH('Nutritional value'!$B20,'Nutritional profile'!$M$2:$W$2,0)),0) -> 0 | ... L20: =_xlfn.IFNA(INDEX('Nutritional profile'!$M$3:$W$11,MATCH('Nutritional value'!L$6,'Nutritional profile'!$B$3:$B$11,0),MATCH('Nutritional value'!$B20,'Nutritional profile'!$M$2:$W$2,0)),0) -> 0 | N20: Processed meat | O20: 0.8587506 | P20: Processed meat | Q20: =C$5*C20/$B$2 -> 0 | R20: =D$5*D20/$B$2 -> 0 | S20: =E$5*E20/$B$2 -> 0 | T20: =F$5*F20/$B$2 -> 0 | U20: =G$5*G20/$B$2 -> 0 | V20: =SUM(Q20:U20) -> 0 | W20: =$O20 -> 0.8587506 | X20: =Q20*$W20 -> 0 | Y20: =R20*$W20 -> 0 | Z20: =S20*$W20 -> 0 | AA20: =T20*$W20 -> 0 | AB20: =U20*$W20 -> 0 | AC20: =SUM(X20:AB20) -> 0 | AE20: Processed meat | AF20: =H$5*H20/$B$2 -> 0 | AG20: =I$5*I20/$B$2 -> 0 | AH20: =J$5*J20/$B$2 -> 0 | AI20: =K$5*K20/$B$2 -> 0 | AJ20: =L$5*L20/$B$2 -> 0 | AK20: =SUM(AF20:AJ20) -> 0 | AL20: =W20 -> 0.8587506 | AM20: =AF20*$AL20 -> 0 | AN20: =AG20*$AL20 -> 0 | AO20: =AH20*$AL20 -> 0 | AP20: =AI20*$AL20 -> 0 | AQ20: =AJ20*$AL20 -> 0 | AR20: =SUM(AM20:AQ20) -> 0
A21: Trans fat | B21: transfat | C21: =_xlfn.IFNA(INDEX('Nutritional profile'!$M$3:$W$11,MATCH('Nutritional value'!C$6,'Nutritional profile'!$B$3:$B$11,0),MATCH('Nutritional value'!$B21,'Nutritional profile'!$M$2:$W$2,0)),0) -> 0.917 | D21: =_xlfn.IFNA(INDEX('Nutritional profile'!$M$3:$W$11,MATCH('Nutritional value'!D$6,'Nutritional profile'!$B$3:$B$11,0),MATCH('Nutritional value'!$B21,'Nutritional profile'!$M$2:$W$2,0)),0) -> 0.063331846 | E21: =_xlfn.IFNA(INDEX('Nutritional profile'!$M$3:$W$11,MATCH('Nutritional value'!E$6,'Nutritional profile'!$B$3:$B$11,0),MATCH('Nutritional value'!$B21,'Nutritional profile'!$M$2:$W$2,0)),0) -> 0.052 | F21: =_xlfn.IFNA(INDEX('Nutritional profile'!$M$3:$W$11,MATCH('Nutritional value'!F$6,'Nutritional profile'!$B$3:$B$11,0),MATCH('Nutritional value'!$B21,'Nutritional profile'!$M$2:$W$2,0)),0) -> 0 | G21: =_xlfn.IFNA(INDEX('Nutritional profile'!$M$3:$W$11,MATCH('Nutritional value'!G$6,'Nutritional profile'!$B$3:$B$11,0),MATCH('Nutritional value'!$B21,'Nutritional profile'!$M$2:$W$2,0)),0) -> 1.0432368 | H21: =_xlfn.IFNA(INDEX('Nutritional profile'!$M$3:$W$11,MATCH('Nutritional value'!H$6,'Nutritional profile'!$B$3:$B$11,0),MATCH('Nutritional value'!$B21,'Nutritional profile'!$M$2:$W$2,0)),0) -> 0.917 | I21: =_xlfn.IFNA(INDEX('Nutritional profile'!$M$3:$W$11,MATCH('Nutritional value'!I$6,'Nutritional profile'!$B$3:$B$11,0),MATCH('Nutritional value'!$B21,'Nutritional profile'!$M$2:$W$2,0)),0) -> 0.063331846 | J21: =_xlfn.IFNA(INDEX('Nutritional profile'!$M$3:$W$11,MATCH('Nutritional value'!J$6,'Nutritional profile'!$B$3:$B$11,0),MATCH('Nutritional value'!$B21,'Nutritional profile'!$M$2:$W$2,0)),0) -> 0 | ... L21: =_xlfn.IFNA(INDEX('Nutritional profile'!$M$3:$W$11,MATCH('Nutritional value'!L$6,'Nutritional profile'!$B$3:$B$11,0),MATCH('Nutritional value'!$B21,'Nutritional profile'!$M$2:$W$2,0)),0) -> 0.0085818824 | N21: Trans fatty acids (TFA) | O21: 4.4429954 | P21: Trans fat | Q21: =C$5*C21/$B$2 -> 0.086363942 | R21: =D$5*D21/$B$2 -> 0.012824007 | S21: =E$5*E21/$B$2 -> 0.025711403 | T21: =F$5*F21/$B$2 -> 0 | U21: =G$5*G21/$B$2 -> 0.41409704 | V21: =SUM(Q21:U21) -> 0.53899639 | W21: =$O21 -> 4.4429954 | X21: =Q21*$W21 -> 0.3837146 | Y21: =R21*$W21 -> 0.056977002 | Z21: =S21*$W21 -> 0.11423564 | AA21: =T21*$W21 -> 0 | AB21: =U21*$W21 -> 1.8398312 | AC21: =SUM(X21:AB21) -> 2.3947585 | AE21: Trans fat | AF21: =H$5*H21/$B$2 -> 0.086363942 | AG21: =I$5*I21/$B$2 -> 0.012824007 | AH21: =J$5*J21/$B$2 -> 0 | AI21: =K$5*K21/$B$2 -> 0 | AJ21: =L$5*L21/$B$2 -> 0.0034064481 | AK21: =SUM(AF21:AJ21) -> 0.1025944 | AL21: =W21 -> 4.4429954 | AM21: =AF21*$AL21 -> 0.3837146 | AN21: =AG21*$AL21 -> 0.056977002 | AO21: =AH21*$AL21 -> 0 | AP21: =AI21*$AL21 -> 0 | AQ21: =AJ21*$AL21 -> 0.015134833 | AR21: =SUM(AM21:AQ21) -> 0.45582643
A22: Sodium | B22: sodi | C22: =_xlfn.IFNA(INDEX('Nutritional profile'!$M$3:$W$11,MATCH('Nutritional value'!C$6,'Nutritional profile'!$B$3:$B$11,0),MATCH('Nutritional value'!$B22,'Nutritional profile'!$M$2:$W$2,0)),0) -> 0.653 | D22: =_xlfn.IFNA(INDEX('Nutritional profile'!$M$3:$W$11,MATCH('Nutritional value'!D$6,'Nutritional profile'!$B$3:$B$11,0),MATCH('Nutritional value'!$B22,'Nutritional profile'!$M$2:$W$2,0)),0) -> 0.31658377 | E22: =_xlfn.IFNA(INDEX('Nutritional profile'!$M$3:$W$11,MATCH('Nutritional value'!E$6,'Nutritional profile'!$B$3:$B$11,0),MATCH('Nutritional value'!$B22,'Nutritional profile'!$M$2:$W$2,0)),0) -> 0.736 | F22: =_xlfn.IFNA(INDEX('Nutritional profile'!$M$3:$W$11,MATCH('Nutritional value'!F$6,'Nutritional profile'!$B$3:$B$11,0),MATCH('Nutritional value'!$B22,'Nutritional profile'!$M$2:$W$2,0)),0) -> 0.24475471 | G22: =_xlfn.IFNA(INDEX('Nutritional profile'!$M$3:$W$11,MATCH('Nutritional value'!G$6,'Nutritional profile'!$B$3:$B$11,0),MATCH('Nutritional value'!$B22,'Nutritional profile'!$M$2:$W$2,0)),0) -> 0.40913047 | H22: =_xlfn.IFNA(INDEX('Nutritional profile'!$M$3:$W$11,MATCH('Nutritional value'!H$6,'Nutritional profile'!$B$3:$B$11,0),MATCH('Nutritional value'!$B22,'Nutritional profile'!$M$2:$W$2,0)),0) -> 0.653 | I22: =_xlfn.IFNA(INDEX('Nutritional profile'!$M$3:$W$11,MATCH('Nutritional value'!I$6,'Nutritional profile'!$B$3:$B$11,0),MATCH('Nutritional value'!$B22,'Nutritional profile'!$M$2:$W$2,0)),0) -> 0.31658377 | J22: =_xlfn.IFNA(INDEX('Nutritional profile'!$M$3:$W$11,MATCH('Nutritional value'!J$6,'Nutritional profile'!$B$3:$B$11,0),MATCH('Nutritional value'!$B22,'Nutritional profile'!$M$2:$W$2,0)),0) -> 0.512 | ... L22: =_xlfn.IFNA(INDEX('Nutritional profile'!$M$3:$W$11,MATCH('Nutritional value'!L$6,'Nutritional profile'!$B$3:$B$11,0),MATCH('Nutritional value'!$B22,'Nutritional profile'!$M$2:$W$2,0)),0) -> 0.24064082 | N22: Sodium | O22: 13.899503 | P22: Sodium | Q22: =C$5*C22/$B$2 -> 0.061500168 | R22: =D$5*D22/$B$2 -> 0.064104752 | S22: =E$5*E22/$B$2 -> 0.36391524 | T22: =F$5*F22/$B$2 -> 0.049560154 | U22: =G$5*G22/$B$2 -> 0.16239814 | V22: =SUM(Q22:U22) -> 0.70147845 | W22: =$O22 -> 13.899503 | X22: =Q22*$W22 -> 0.85482177 | Y22: =R22*$W22 -> 0.8910242 | Z22: =S22*$W22 -> 5.0582409 | AA22: =T22*$W22 -> 0.68886151 | AB22: =U22*$W22 -> 2.2572534 | AC22: =SUM(X22:AB22) -> 9.7502018 | AE22: Sodium | AF22: =H$5*H22/$B$2 -> 0.061500168 | AG22: =I$5*I22/$B$2 -> 0.064104752 | AH22: =J$5*J22/$B$2 -> 0.25315843 | AI22: =K$5*K22/$B$2 -> 0.040847006 | AJ22: =L$5*L22/$B$2 -> 0.095518726 | AK22: =SUM(AF22:AJ22) -> 0.51512908 | AL22: =W22 -> 13.899503 | AM22: =AF22*$AL22 -> 0.85482177 | AN22: =AG22*$AL22 -> 0.8910242 | AO22: =AH22*$AL22 -> 3.5187763 | AP22: =AI22*$AL22 -> 0.56775308 | AQ22: =AJ22*$AL22 -> 1.3276628 | AR22: =SUM(AM22:AQ22) -> 7.1600382
A23: We have use the Index (array) to automatically look at the corresponding value in the Nutritional profile table, no need to do anything here | U23: Total DANI (μDALY/serving) | X23: =SUM(X7:X22) -> 0.81327235 | Y23: =SUM(Y7:Y22) -> -3.8155191 | Z23: =SUM(Z7:Z22) -> 2.3974866 | AA23: =SUM(AA7:AA22) -> 0.58919963 | AB23: =SUM(AB7:AB22) -> 7.5202426 | AC23: =SUM(AC7:AC22) -> 7.5046821 | AJ23: Total DANI (μDALY/serving) | AM23: =SUM(AM7:AM22) -> 0.81327235 | AN23: =SUM(AN7:AN22) -> -3.8155191 | AO23: =SUM(AO7:AO22) -> -9.8462362 | AP23: =SUM(AP7:AP22) -> -1.9382558 | AQ23: =SUM(AQ7:AQ22) -> -1.5529743 | AR23: =SUM(AR7:AR22) -> -16.339713
U24: Total HENI (Minutes of Healthy lifetime gained/serving) | X24: =X23*$R$2 -> -0.42774872 | Y24: =Y23*$R$2 -> 2.0068104 | Z24: =Z23*$R$2 -> -1.2609821 | AA24: =AA23*$R$2 -> -0.30989544 | AB24: =AB23*$R$2 -> -3.9553468 | AC24: =AC23*$R$2 -> -3.9471626 | AJ24: Total HENI (Minutes of Healthy lifetime gained/serving) | AM24: =AM23*$R$2 -> -0.42774872 | AN24: =AN23*$R$2 -> 2.0068104 | AO24: =AO23*$R$2 -> 5.1787264 | AP24: =AP23*$R$2 -> 1.019445 | AQ24: =AQ23*$R$2 -> 0.81680239 | AR24: =AR23*$R$2 -> 8.5940355
U25: Contribution (%) | X25: =X24/$AC$24 -> 0.10836866 | Y25: =Y24/$AC$24 -> -0.50841848 | Z25: =Z24/$AC$24 -> 0.31946545 | AA25: =AA24/$AC$24 -> 0.078510938 | AB25: =AB24/$AC$24 -> 1.0020734 | AJ25: Contribution (%)

Sheet Nutritional assessment
A1: Per serving
A2: Foodcode | B2: Foodcode Description | C2: Main Group Description | D2: Category Description | E2: Increase in saturated fats | F2: Increase in calcium - detrimental (male) | G2: Increase in calcium - protective | H2: Increase in fiber with mediation | I2: Increase in fiber | J2: Increase in fruits | K2: Increase in milk | L2: Increase in nuts and seeds | M2: Increase in polyunsaturated fatty acids | N2: Increase in processed meat | O2: Increase in red meat | P2: Increase in seafood omega-3 fatty acids | Q2: Increase in sodium | R2: Increase in sugar-sweetened beverages | S2: Increase in trans fatty acids | T2: Increase in vegetables | U2: Increase in whole grains | V2: Total
A3: 58100160 | B3: Burrito with beef, beans, rice, and cheese | C3: Mixed Dishes | D3: Burritos and tacos | E3: -4.8288688 | F3: -0.53587271 | G3: 1.423401 | H3: 0 | I3: 0 | J3: 0 | K3: 2.0834796 | L3: 0 | M3: 0.15670946 | N3: 0 | O3: 0 | P3: 0 | Q3: -0.83524937 | R3: 0 | S3: -0.38441664 | T3: 0 | U3: 0 | V3: =SUM(E3:U3) -> -2.9208174

Sheet Nutritional profile
A1: per 100 g
A2: ID | C2: Cycle | D2: Foodcode | E2: Foodcode Description | F2: Main Group No | G2: Main Group Description | H2: Subgroup No | I2: Subgroup Description | J2: Category No | K2: Category Description | L2: Racc | M2: fiber_fvlw | N2: sfat | O2: calc | P2: fiber_non_fvlw | Q2: pfat | R2: whole_grain | S2: legumes | T2: vegetable | U2: sodi | V2: red_meat | W2: transfat
A3: 4_14104010 | B3: Cheese, cheddar (g/100g) | C3: 4 | D3: 14104100 | E3: Cheese, Cheddar | F3: 1 | G3: Milk and Dairy | H3: 16 | I3: Cheese | J3: 1602 | K3: Cheese | L3: 30 | M3: 0 | N3: 18.867 | O3: 0.71 | P3: 0 | Q3: 1.421 | R3: 0 | S3: 0 | T3: 0 | U3: 0.653 | V3: 0 | W3: 0.917
A4: 4_52215200 | B4: Tortilla (g/100g) | C4: 4 | D4: 52215200 | E4: Tortilla, flour (wheat) | F4: 4 | G4: Grains | H4: 42 | I4: Breads, Rolls, Tortillas | J4: 4208 | K4: Tortillas | L4: 55 | M4: 0 | N4: 2.924 | O4: 0.146 | P4: 3.5 | Q4: 2.29 | R4: 0 | S4: 0 | T4: 0 | U4: 0.736 | V4: 0 | W4: 0.052
A5: 4_41205010 | B5: Refried beans (g/100g) | C5: 4 | D5: 41205010 | E5: Refried beans | F5: 2 | G5: Protein Foods | H5: 28 | I5: Plant-based Protein Foods | J5: 2802 | K5: Beans, peas, legumes | L5: 130 | M5: 5.2619278 | N5: 0.96625692 | O5: 0.034319769 | P5: 0 | Q5: 2.1324946 | R5: 0 | S5: 88.053738 | T5: 7.1475153 | U5: 0.31658377 | V5: 0 | W5: 0.063331846
A6: 4_21501000 | B6: Ground beef (g/100g) | C6: 4 | D6: 21501000 | E6: Ground beef, less than 80% lean, cooked (formerly regular) | F6: 2 | G6: Protein Foods | H6: 20 | I6: Meats | J6: 2004 | K6: Ground beef | L6: 85 | M6: 0 | N6: 6.2286791 | O6: 0.031933412 | P6: 0 | Q6: 0.44724318 | R6: 0 | S6: 0 | T6: 0 | U6: 0.40913047 | V6: 91.369992 | W6: 1.0432368
A7: 4_56205010 | B7: Rice, white (g/100g) | C7: 4 | D7: 56205001 | E7: Rice, white, cooked, NS as to fat added in cooking | F7: 4 | G7: Grains | H7: 40 | I7: Cooked Grains | J7: 4002 | K7: Rice | L7: 140 | M7: 5.5514286e-17 | N7: 0.076515714 | O7: 0.010088071 | P7: 0.39748429 | Q7: 0.075522 | R7: 0 | S7: 0 | T7: 0 | U7: 0.24475471 | V7: 0 | W7: 0
A9: 4_56205110 | B9: Rice, brown (g/100g) | C9: 4 | D9: 56205011 | E9: Rice, brown, cooked, NS as to fat added in cooking | F9: 4 | G9: Grains | H9: 40 | I9: Cooked Grains | J9: 4002 | K9: Rice | L9: 140 | M9: 1.5918367 | N9: 0.2586735 | O9: 0.0031071429 | P9: 0 | Q9: 0.36413264 | R9: 34.410536 | S9: 0 | T9: 0 | U9: 0.2017245 | V9: 0 | W9: 0
A10: 4_75340140 | B10: Vegetable combination (g/100g) | C10: 4 | D10: 75200121 | E10: Vegetables, NS as to type, cooked, made with oil | F10: 7 | G10: Vegetables | H10: 64 | I10: Vegetables, excluding Potatoes | J10: 6420 | K10: Other vegetables and combinations | L10: 85 | M10: 2.1349885 | N10: 0.36131047 | O10: 0.024395294 | P10: 2.1349885 | Q10: 1.0674294 | R10: 0 | S10: 0 | T10: 48.522465 | U10: 0.24064082 | V10: 0 | W10: 0.0085818824
A11: 4_52215260 | B11: Tortilla, whole wheat (g/100g) | C11: 4 | D11: 52215260 | E11: Tortilla, whole wheat | F11: 4 | G11: Grains | H11: 42 | I11: Breads, Rolls, Tortillas | J11: 4208 | K11: Tortillas | L11: 55 | M11: 9.8 | N11: 4.878 | O11: 0.244 | P11: 0 | Q11: 0.992 | R11: 68 | S11: 0 | T11: 0 | U11: 0.512 | V11: 0 | W11: 0

Sheet DRF
A1: Dietary risk | B1: DRFs
B2: (avoided μDALY/g)
A3: Omega-3 (seafood) | B3: 57.09
A4: Calcium (protective) | B4: 4.9
A5: Nuts and seeds | B5: 1.83
A6: Fiber (from other sources) | B6: 1.04
A7: PUFA | B7: 0.66
A8: Whole grains | B8: 0.45
A9: Fruits | B9: 0.2
