Workbook

Sheet Directions
A1: Impact Assessment hands drying: Hands-on Learning impact assessment on your own
A3: 1. Use the inventory data and characterization factorsfrom part A to fill in the impact assessment tables below (e.g. cells B41 to D44) to estimate for the two hand dryer scenarios
A4: the respiratory inorganics (fine particulate) and global warming impacts on human health, first at midpoint level
A5: (in kgPM2.5 equivalent/FU for PM and kg CO2 equivalent/FU for Global warming )
A7: 2. Based on these results, identify the substance dominating substances and discuss this at the bottom of each table (e.g. cell B49)
A9: 3. Use the Midpoint to Damage factors to fill-in the bottom of each impact assessment table (e.g cells D45 to D48) and to calculate damages in DALY/FU
A11: 4. Based on the midpoint and damage results, fill in the summary table (C66 to D68) linking it to the final results of each table and discuss what is the best of the two scenarios
A12: from a human health perspective (considering these two impact categories) and what is the dominant impact category for each scenario (cells C70 & C71)

Sheet Impact Assessment
A3: A. Inventory data
A4: Scenarios | B4: Functional Unit | C4: CO2 [kgCO2 /unit] | D4: CH4 [kgCH4 /unit] | E4: N2O [kgN20 /unit] | F4: PM10 [kgPM10 /unit] | G4: PM2.5 [kgPM2.5 /unit] | H4: NOx [kgNOx /unit] | I4: SOx [kgSOx/unit]
A5: Air dryer | B5: 1 pair of hands dried | C5: 0.011 | D5: 2.3e-05 | E5: 7.2e-08 | F5: 1.5e-06 | G5: 3.6e-10 | H5: 1.4e-05 | I5: 4.8e-05
A6: Paper towels | C6: 0.001 | D6: 1.8e-07 | E6: 4.1e-07 | F6: 2.4e-08 | G6: 4.2e-06 | H6: 3.1e-05 | I6: 3.7e-07
A8: B. Impact Assessment Characterization factors
A9: Column1 | B9: Comparable unit | C9: CO2 [kgCO2 ] | D9: CH4 [kgCH4 ] | E9: N2O [kgN20 ] | F9: PM10 [kgPM10 ] | G9: PM2.5 [kgPM2.5 ] | H9: NOx [kgNOx ] | I9: SOx [kgSOx]
A10: Global Warming Potential | B10: kgCO2eq | C10: 1 | D10: 34 | E10: 298 | F10: 0 | G10: 0 | H10: 0 | I10: 0
A11: Respiratory Inorganics - Fine Particulate | B11: kgPM2.5eq | C11: 0 | D11: 0 | E11: 0 | F11: 0.6 | G11: 1 | H11: 0.0077 | I11: 0.038
A13: C. Midpoint to damage factors
A14: Column1 | B14: Midpoint-to-Damage Factor
B15: MDFjk
A16: Respiratory | B16: 0.00083
A17: Inorganics
A18: (DALY/kgPM2.5eq.)
A19: Global warming (DALY/kgCO2eq.) | B19: 8.30 × 10–7
A23: D. Impact Assessment tables
A25: Air Dryer scenario | G25: Paper Towel scenario
A27: Respiratory Inorganics | B27: Emission per FU: bi | C27: Characterization factor midpoint: CFi | D27: Midpoint score per FU: Sj | G27: Respiratory Inorganics | H27: Emission per FU: bi | I27: Characterization factor midpoint: CFi | J27: Midpoint score per FU: Sj
B28: [kg/FU] | C28: [kgPM2.5eq/ kg] | D28: [kgeqPM2.5/FU] | H28: [kg/FU] | I28: [kgPM2.5eq/ kg] | J28: [kgeqPM2.5/FU]
A29: Substance #1: PM10 | G29: Substance #1: PM10
A30: Substance #2: PM2.5 | G30: Substance #2: PM2.5
A31: Substance #3: NOx | G31: Substance #3: NOx
A32: Substance #4: SOx | G32: Substance #4: SOx
C33: Total midpoint damage [kgPM2.5eq./FU] | D33: =SUM(D29:D32) -> 0 | I33: Total midpoint damage [kgPM2.5eq./FU] | J33: =SUM(J29:J32) -> 0
C34: Midpoint to damage factor [DALY/kgPM2.5eq.] | I34: Midpoint to damage factor [DALY/kgPM2.5eq.]
C35: Total endpoint damage [DALY/FU] | I35: Total endpoint damage [DALY/FU]
A37: Dominant substance to total score: | G37: Dominant substance to total score:
A40: Global warming | B40: Emission per FU: bi | C40: Characterization factor midpoint CFi | D40: Midpoint score per FU: Sk | G40: Global warming | H40: Emission per FU: bi | I40: Characterization factor midpoint CFi | J40: Midpoint score per FU: Sk
B41: [kg/FU] | C41: [kgCO2eq./ kg] | D41: [kgCO2eq./FU] | H41: [kg/FU] | I41: [kgCO2eq./ kg] | J41: [kgCO2eq./FU]
A42: Substance #1: CO2 | G42: Substance #1: CO2
A43: Substance #2: CH4 | G43: Substance #2: CH4
A44: Substance #3: N20 | G44: Substance #3: N20
C45: Total midpoint damage [kgCO2eq./FU] | D45: =SUM(D42:D44) -> 0 | I45: Total midpoint damage [kgCO2eq./FU] | J45: =SUM(J42:J44) -> 0
C46: Midpoint to damage factor [DALY/kgCO2eq.] | I46: Midpoint to damage factor [DALY/kgCO2eq.]
C47: Total endpoint damage [DALY/FU] | I47: Total endpoint damage [DALY/FU]
A49: Dominant substance to total score: | G49: Dominant substance to total score:
A51: Summary table - HH damage
A53: Column1 | B53: Column2 | C53: Air dryer | D53: Paper towel
A54: Respiratory Inorganics | B54: Endpoint damage [DALY/FU]
A55: Global warming | B55: Endpoint damage [DALY/FU]
...

Sheet Calculations
A1: Summary
A6: Column1 | B6: Column2 | C6: Air Dryer | D6: paper towel
A7: Fine particulate midp | B7: kg PM2.5 | C7: ='Impact Assessment'!D33 -> 0 | D7: ='Impact Assessment'!J33 -> 0
A8: Fine particulate damaage | B8: Total DALY/FU | C8: ='Impact Assessment'!D35 -> 0 | D8: ='Impact Assessment'!J35 -> 0
A9: Dominant substance to total score: | C9: ='Impact Assessment'!B37 -> 0 | D9: ='Impact Assessment'!H37 -> 0
A11: GW midpoint | C11: ='Impact Assessment'!D45 -> 0 | D11: ='Impact Assessment'!J45 -> 0
A12: GW damage | B12: Total DALY/FU | C12: ='Impact Assessment'!D47 -> 0 | D12: ='Impact Assessment'!J47 -> 0
A13: Dominant substance to total score: | C13: ='Impact Assessment'!B49 -> 0 | D13: ='Impact Assessment'!H49 -> 0
A15: Total HH | B15: Total DALY/FU | C15: ='Impact Assessment'!C56 -> 0 | D15: ='Impact Assessment'!D56 -> 0
A16: ='Impact Assessment'!A58 -> Best scenario: | C16: ='Impact Assessment'!B58 -> 0
A17: ='Impact Assessment'!A59 -> Most contributing category to total DALY | C17: ='Impact Assessment'!B59 -> 0
